Workbook

Sheet Disclaimer
B6: Disclaimer:
B8: Português:
B9: - A aba OPERATIONAL INFO contém informações operacionais divulgadas como, por exemplo, ARR, produção de crédito, entre outras
B10: - A aba GAAP-Consolidated-P&L possui o Demonstrativo de Resultado (GAAP)
B11: - A aba GAAP-Consolidated-BS possui o Balanço Patrimonial (GAAP) com a operação de Techfin Desconsolidada
B12: - A aba GAAP-Consolidated-CF possui o Fluxo de Caixa (GAAP) com a operação de Techfin Desconsolidada
B13: - A aba Non-GAAP-Consolidated-P&L possui o EBITDA Consolidado com o resultado da operação de Techfin à 50% em todos os períodos
B14: - A aba Non-GAAP-Techfin-P&L possui o Demonstrativo de Resultado Non-GAAP da Dimensão de Techin sem os efeitos do FIDC
B15: - A aba Non-GAAP-Techfin-BS Techfin wo FIDC possui o Balanço Patrimonial Non-GAAP da Dimensão de Techin sem os efeitos do FIDC
B16: - A aba Non-GAAP-Techfin-CF Techfin wo FIDC possui o Fluxo de Caixa Non-GAAP da Dimensão de Techin sem os efeitos do FIDC
B17: - As informações contidas na aba CONTRIB MGN PRO FORMA demonstram as margens de contribuição Pró-Forma de Business Performance e Techfin, considerando os resultados não auditados de janeiro a maio de 2020 da Supplier, de janeiro a dezembro de 2020 da Tail Target e de janeiro de 2020 a maio de 2021 da RD station.
B18: - As informações contidas na aba IS - 2015 to 2018 estão separadas entre Software e Hardware
... B32: - Information presented in the IS - 2018 to 2020 sheet has the consolidated Income Statements for the years 2018 to 2020

Sheet OPERATIONAL INFO
A1: PORTUGUÊS | B1: ENGLISH
A2: Informações Operacionais | B2: Operational Informations | C2: 1Q21 | D2: 2Q21 | E2: 3Q21 | F2: 4Q21 | G2: 1Q22 | H2: 2Q22 | I2: 3Q22 | J2: 4Q22 | K2: 1Q23 | L2: 2Q23 | M2: 3Q23 | N2: 4Q23 | O2: 1Q24 | P2: 2Q24 | Q2: 3Q24 | R2: 4Q24 | S2: 1Q25 | T2: 2Q25 | U2: 3Q25
A4: Consolidado | B4: Management
A5: ARR (R$ milhões) | B5: ARR (R$ million) | C5: =SUM(C6:C8) -> 2265.3934 | D5: =SUM(D6:D8) -> 2595.1044 | E5: =SUM(E6:E8) -> 2751.9757 | F5: =SUM(F6:F8) -> 3002.5216 | G5: =SUM(G6:G8) -> 3279.5606 | H5: =SUM(H6:H8) -> 3530.9156 | I5: =SUM(I6:I8) -> 3740.0856 | J5: =SUM(J6:J8) -> 3939.8936 | ... U5: =SUM(U6:U8) -> 6270.6186
A6: Baseline | B6: Baseline | C6: 2164.2664 | D6: 2265.3934 | E6: 2595.1044 | F6: 2751.9757 | G6: 3002.5216 | H6: 3297.6396 | I6: 3530.9156 | J6: 3740.0856 | K6: 3939.8936 | L6: 4121.4256 | M6: 4329.5306 | N6: 4496.7136 | O6: 4659.1476 | P6: 4875.6306 | Q6: 5118.2156 | R6: 5291.6646 | S6: 5480.0046 | T6: 5771.7866 | U6: 5985.1126
A7: Adição Líquida de ARR | B7: ARR Net Addition | C7: 87.212 | D7: 117.707 | E7: 156.87131 | F7: 250.54583 | G7: 262.583 | H7: 204.711 | I7: 182.769 | J7: 189.324 | K7: 181.532 | L7: 178.047 | M7: 167.183 | N7: 182.55 | O7: 182.283 | P7: 168.953 | Q7: 173.449 | R7: 188.34 | S7: 278.45 | T7: 213.326 | U7: 220.231
A8: Adição Inorgânica | B8: Inorganic Addition | C8: 13.915 | D8: 212.004 | E8: 0 | F8: 0 | G8: 14.456 | H8: 28.565 | I8: 26.401 | J8: 10.484 | K8: 0 | L8: 30.058 | M8: 0 | N8: -20.116 | O8: 34.2 | P8: 73.632 | Q8: 0 | R8: 0 | S8: 13.332 | T8: 0 | U8: 65.275
A10: Gestão | B10: Management
A11: ARR (R$ milhões) | B11: ARR (R$ million) | C11: =SUM(C12:C14) -> 2262.0264 | D11: =SUM(D12:D14) -> 2379.0674 | E11: =SUM(E12:E14) -> 2515.4387 | F11: =SUM(F12:F14) -> 2750.9316 | G11: =SUM(G12:G14) -> 3028.4536 | H11: =SUM(H12:H14) -> 3243.6256 | I11: =SUM(I12:I14) -> 3429.5126 | J11: =SUM(J12:J14) -> 3613.9356 | ... U11: =SUM(U12:U14) -> 5660.1836
A12: Baseline | B12: Baseline | C12: 2161.0974 | D12: 2262.0264 | E12: 2379.0674 | F12: 2515.4387 | G12: 2750.9316 | H12: 3028.4536 | I12: 3243.6256 | J12: 3429.5126 | K12: 3613.9356 | L12: 3769.1636 | M12: 3915.6896 | N12: 4052.8586 | O12: 4192.4156 | P12: 4385.9996 | Q12: 4606.8996 | R12: 4764.6496 | S12: 4936.4896 | T12: 5206.4376 | U12: 5397.8336
A13: Adição Líquida de ARR | B13: ARR Net Addition | C13: 87.014 | D13: 117.041 | E13: 136.37131 | F13: 235.49283 | G13: 263.066 | H13: 186.607 | I13: 164.501 | J13: 173.939 | K13: 155.228 | L13: 146.526 | M13: 137.169 | N13: 159.673 | O13: 159.384 | P13: 147.268 | Q13: 157.75 | R13: 171.84 | S13: 256.616 | T13: 191.396 | U13: 197.075
A14: Adição Inorgânica | B14: Inorganic Addition | C14: 13.915 | D14: 0 | E14: 0 | F14: 0 | G14: 14.456 | H14: 28.565 | I14: 21.386 | J14: 10.484 | K14: 0 | L14: 0 | M14: 0 | N14: -20.116 | O14: 34.2 | P14: 73.632 | Q14: 0 | R14: 0 | S14: 13.332 | T14: 0 | U14: 65.275
A15: Taxa de Retenção | B15: Retention Rate | C15: 0.9805 | D15: 0.988 | E15: 0.983 | F15: 0.9799 | G15: 0.988 | H15: 0.9849 | I15: 0.9857 | J15: 0.9903 | K15: 0.9797 | L15: 0.9829 | M15: 0.9817 | N15: 0.9754 | O15: 0.9869 | P15: 0.9821 | Q15: 0.9858 | R15: 0.9887 | S15: 0.9828 | T15: 0.9829 | U15: 0.98613
A17: RD Station | B17: RD Station
A18: ARR SaaS (R$ milhões) | B18: SaaS ARR (R$ million) | C18: =SUM(C19:C21) -> 3.367 | D18: =SUM(D19:D21) -> 216.037 | E18: =SUM(E19:E21) -> 236.537 | F18: =SUM(F19:F21) -> 251.59 | G18: =SUM(G19:G21) -> 269.186 | H18: =SUM(H19:H21) -> 287.29 | I18: =SUM(I19:I21) -> 310.573 | J18: =SUM(J19:J21) -> 325.958 | ... U18: =SUM(U19:U21) -> 610.435
A19: Baseline | B19: Baseline | C19: 3.169 | D19: 3.367 | E19: 216.037 | F19: 236.537 | G19: 251.59 | H19: 269.186 | I19: 287.29 | J19: 310.573 | K19: 325.958 | L19: 352.262 | M19: 413.841 | N19: 443.855 | O19: 466.732 | P19: 489.631 | Q19: 511.316 | R19: 527.015 | S19: 543.515 | T19: 565.349 | U19: 587.279
A20: Adição Líquida de ARR | B20: ARR Net Addition | C20: 0.198 | D20: 0.666 | E20: 20.5 | F20: 15.053 | G20: 17.596 | H20: 18.104 | I20: 18.268 | J20: 15.385 | K20: 26.304 | L20: 31.521 | M20: 30.014 | N20: 22.877 | O20: 22.899 | P20: 21.685 | Q20: 15.699 | R20: 16.5 | S20: 21.834 | T20: 21.93 | U20: 23.156
A21: Adição Inorgânica | B21: Inorganic Addition | C21: 0 | D21: 212.004 | E21: 0 | F21: 0 | G21: 0 | H21: 0 | I21: 5.015 | J21: 0 | K21: 0 | L21: 30.058 | M21: 0 | N21: 0 | O21: 0 | P21: 0 | Q21: 0 | R21: 0 | S21: 0 | T21: 0 | U21: 0
A22: Taxa de Retenção SaaS | B22: SaaS Retention Rate | C22: 0.9224 | D22: 0.9745 | E22: 0.979 | F22: 0.977 | G22: 0.9766 | H22: 0.9734 | I22: 0.9714 | J22: 0.9753 | K22: 0.9531 | L22: 0.951 | M22: 0.949 | N22: 0.9506 | O22: 0.9169 | P22: 0.9439 | Q22: 0.944 | R22: 0.9454 | S22: 0.9498 | T22: 0.9474 | U22: 0.9475
A24: Techfin | B24: Techfin
A25: Produção de Crédito (R$ milhões) | B25: Credit Production (R$ million) | C25: 2043.0158 | D25: 2438.294 | E25: 2665.8744 | F25: 2624.2087 | G25: 2562.5826 | H25: 2646.5157 | I25: 2908.7334 | J25: 2702.6311 | K25: 2524.7986 | L25: 2483.3088 | M25: 2885.6232 | N25: 2735.619 | O25: 2618.485 | P25: 2791.1 | Q25: 3047.242 | R25: 3414.679 | S25: 3208.912 | T25: 3237.892 | U25: 3393.912
A26: Prazo médio de Produção de Crédito (dias) | B26: Average Term of Credit Production (days) | C26: 57.18 | D26: 51.9 | E26: 55.25 | F26: 61.41 | G26: 58.41 | H26: 54.03 | I26: 62.49 | J26: 68.81 | K26: 60.83 | L26: 55.9 | M26: 74.14 | N26: 70.27 | O26: 65.02 | P26: 59.52 | Q26: 64.15 | R26: 69.55 | S26: 64.68 | T26: 60.34 | U26: 67.14
A27: Carteira de Crédito Supplier (R$ milhões) | B27: Supplier Funding Cost (R$ million) | C27: 1391.8783 | D27: 1491.0133 | E27: 1584.2727 | F27: 1548.0262 | G27: 1813.5466 | H27: 1763.1342 | I27: 1802.7891 | J27: 1834.3134 | K27: 1965.0837 | L27: 1805.883 | M27: 1978.049 | N27: 2086.9096 | O27: 2325.5598 | P27: 2112.9116 | Q27: 2142.539 | R27: 2152.5246 | S27: 2471.812 | T27: 2472.7102 | U27: 2380.1684
A28: Prazo médio calculado Carteira em dia (dias) | B28: Calculated Average Term of On Due Portfolio (days) | C28: =C30/(C25/90) -> 61.006005 | D28: =D30/(D25/90) -> 54.953952 | E28: =E30/(E25/90) -> 53.415255 | F28: =F30/(F25/90) -> 53.09756 | G28: =G30/(G25/90) -> 62.890183 | H28: =H30/(H25/90) -> 59.390873 | I28: =I30/(I25/90) -> 55.251822 | J28: =J30/(J25/90) -> 60.541684 | ... U28: =U30/(U25/90) -> 61.876009
A29: Direitos Credit. da Supplier por Venc. (Em R$ milhões) | B29: Supplier's Credit Rights by Maturity (In R$ million) | C29: =C38+C39 -> 1392.845 | D29: =D38+D39 -> 1499.527 | E29: =E38+E39 -> 1594.86 | F29: =F38+F39 -> 1566.134 | G29: =G38+G39 -> 1813.547 | H29: =H38+H39 -> 1763.136 | I29: =I38+I39 -> 1802.79 | J29: =J38+J39 -> 1834.3156 | ... U29: =U38+U39 -> 2380.1684
A30: A vencer | B30: On Due | C30: 1384.847 | D30: 1488.821 | E30: 1582.204 | F30: 1548.212 | G30: 1790.681 | H30: 1746.432 | I30: 1785.698 | J30: 1818.0204 | K30: 1950.4056 | L30: 1786.6374 | M30: 1964.7743 | N30: 2069.7873 | O30: 2308.9406 | P30: 2088.8085 | Q30: 2125.3346 | R30: 2120.8833 | S30: 2446.435 | T30: 2427.7873 | U30: 2333.3525
A31: Títulos Vencidos | B31: Notes overdue
A32: Até 30 dias | B32: Up to 30 days | C32: 8.151 | D32: 12.353 | E32: 14.881 | F32: 17.448 | G32: 21.205 | H32: 16.285 | I32: 16.108 | J32: 20.529591 | K32: 14.080934 | L32: 14.608075 | M32: 13.076076 | N32: 15.13229 | O32: 13.30087 | P32: 18.589769 | Q32: 14.33117 | R32: 33.34594 | S32: 22.331 | T32: 43.90649 | U32: 29.93243
A33: de 31 a 60 dias | B33: from 31 to 60 days | C33: 1.315 | D33: 1.929 | E33: 2.138 | F33: 3.933 | G33: 5.704 | H33: 4.097 | I33: 4.2189141 | J33: 5.2642987 | K33: 3.9818165 | L33: 4.5809696 | M33: 4.5020463 | N33: 5.52732 | O33: 4.95896 | P33: 6.4119039 | Q33: 5.05639 | R33: 2.75683 | S33: 7.653 | T33: 5.52404 | U33: 3.83022
A34: de 61 a 90 dias | B34: from 61 to 90 days | C34: 1.222 | D34: 1.459 | E34: 2.037 | F34: 2.874 | G34: 5.296 | H34: 3.485 | I34: 3.8500465 | J34: 6.4600933 | K34: 3.9330058 | L34: 6.2493691 | M34: 3.7782825 | N34: 4.00276 | O34: 4.44359 | P34: 4.2492448 | Q34: 3.3092 | R34: 2.89424 | S34: 3.54 | T34: 4.05755 | U34: 8.92841
A35: de 91 a 180 dias | B35: from 91 to 180 days | C35: 2.167 | D35: 2.682 | E35: 3.604 | F35: 5.27 | G35: 8.255 | H35: 11.503 | I35: 9.18 | J35: 9.6219498 | K35: 18.311 | L35: 15.326625 | M35: 8.4839869 | N35: 10.68817 | O35: 10.15961 | P35: 11.121737 | Q35: 10.35126 | R35: 8.00301 | S35: 7.512 | T35: 10.736 | U35: 26.89417
A36: de 181 a 360 dias | B36: from 181 to 360 days | C36: 7.483 | D36: 3.542 | E36: 4.547 | F36: 6.874 | G36: 7.824 | H36: 11.536 | I36: 16.686 | J36: 18.079806 | K36: 16.579 | L36: 20.262948 | M36: 24.404643 | N36: 21.03753 | O36: 22.87725 | P36: 18.313719 | Q36: 17.16877 | R36: 17.95082 | S36: 15.831 | T36: 12.95949 | U36: 13.23948
A37: mais de 360 dias | B37: over 360 days | C37: 49.504 | D37: 54.681 | E37: 55.755 | F37: 57.25 | G37: 59.101 | H37: 61.206 | I37: 64.958 | J37: 70.638322 | K37: 79.173 | L37: 85.380159 | M37: 93.0808 | N37: 103.63531 | O37: 110.39034 | P37: 122.38778 | Q37: 131.14813 | R37: 137.99645 | S37: 144.569 | T37: 149.10342 | U37: 153.60587
A38: Contas a receber bruto | B38: Gross Trade Receivables | C38: =SUM(C30,C32:C37) -> 1454.689 | D38: =SUM(D30,D32:D37) -> 1565.467 | E38: =SUM(E30,E32:E37) -> 1665.166 | F38: =SUM(F30,F32:F37) -> 1641.861 | G38: =SUM(G30,G32:G37) -> 1898.066 | H38: =SUM(H30,H32:H37) -> 1854.544 | I38: =SUM(I30,I32:I37) -> 1900.699 | J38: =SUM(J30,J32:J37) -> 1948.6145 | ... U38: =SUM(U30,U32:U37) -> 2569.7831
A39: (-) Provisão para perda esperada | B39: Provision for Expected Credit Losses | C39: -61.844 | D39: -65.94 | E39: -70.306 | F39: -75.727 | G39: -84.519 | H39: -91.408 | I39: -97.909 | J39: -114.29884 | K39: -121.374 | L39: -127.14955 | M39: -134.04241 | N39: -142.90106 | O39: -149.51146 | P39: -156.97106 | Q39: -164.16058 | R39: -171.30599 | S39: -176.059 | T39: -181.36415 | U39: -189.6147
A40: Caixa - Operação de Crédito (R$ milhões) | B40: Cash Position - Credit Operation (R$ million) | C40: 305.9428 | D40: 444.69132 | E40: 679.15073 | F40: 523.46124 | G40: 293.55753 | H40: 494.11898 | I40: 629.53824 | J40: 619.2657 | K40: 311.13406 | L40: 784.68239 | M40: 274.95486 | N40: 334.89447 | O40: 189.47522 | P40: 433.0831 | Q40: 386.33089 | R40: 91.23722 | S40: 206.10168 | T40: 195.90543 | U40: 336.45193
A41: Inadimplência acima de 90 dias | B41: Delinquency Rate above 90 days
A42: Techfin | B42: Techfin | C42: 0.0073152 | D42: 0.005 | E42: 0.0063 | F42: =SUM(F35:F36)/SUM(F30:F36) -> 0.0076637105 | G42: =SUM(G35:G36)/SUM(G30:G36) -> 0.0087435052 | H42: =SUM(H35:H36)/SUM(H30:H36) -> 0.012846993 | I42: =SUM(I35:I36)/SUM(I30:I36) -> 0.014090223 | J42: =SUM(J35:J36)/SUM(J30:J36) -> 0.014750856 | K42: =SUM(K35:K36)/SUM(K30:K36) -> 0.017381632 | L42: =SUM(L35:L36)/SUM(L30:L36) -> 0.019261914 | M42: =SUM(M35:M36)/SUM(M30:M36) -> 0.016289408 | ... U42: =SUM(U35:U36)/SUM(U30:U36) -> 0.016610391
A43: Média Brasil | B43: Brazil Average | C43: 0.024 | D43: 0.03 | E43: 0.025 | F43: 0.026 | G43: 0.026 | H43: 0.026 | I43: 0.028 | J43: 0.032 | K43: 0.036 | L43: 0.039 | M43: 0.04 | N43: 0.041 | O43: 0.044 | P43: 0.044 | Q43: 0.045 | R43: 0.045 | S43: 0.046 | T43: 0.051 | U43: 0.054

Sheet GAAP-Consolidated-P&L
A1: PORTUGUÊS | B1: ENGLISH
A2: Demonstração de Resultados GAAP Trimestre (em R$ mil) | B2: GAAP Income Statement Quarter (in R$ thousand) | C2: 1Q21 | D2: 2Q21 | E2: 3Q21 | F2: 4Q21 | G2: 1Q22 | H2: 2Q22 | I2: 3Q22 | J2: 4Q22 | K2: 1Q23 | L2: 2Q23 | M2: 3Q23 | N2: 4Q23 | O2: 1Q24 | P2: 2Q24 | Q2: 3Q24 | R2: 4Q24 | S2: 1Q25 | T2: 2Q25 | U2: 3Q25
A3: Resultado de Gestão | B3: Management Result
A4: Receita Líquida | B4: Net Revenue | C4: =C5+C6 -> 653821 | D4: =D5+D6 -> 672848 | E4: =E5+E6 -> 712293 | F4: =F5+F6 -> 754053 | G4: =G5+G6 -> 819459 | H4: =H5+H6 -> 830971 | I4: =I5+I6 -> 883523 | J4: =J5+J6 -> 908332 | ... U4: =U5+U6 -> 1393406
A5: Recorrente | B5: Recurring | C5: 529041 | D5: 554322 | E5: 583967 | F5: 623285 | G5: 668764 | H5: 705609 | I5: 748781 | J5: 780492 | K5: 800624 | L5: 832012 | M5: 873258 | N5: 899958 | O5: 936972 | P5: 1001235 | Q5: 1045609 | R5: 1090015 | S5: 1160357 | T5: 1198126 | U5: 1266752
A6: Não Recorrente | B6: Non Recurring | C6: =C7+C8 -> 124780 | D6: =D7+D8 -> 118526 | E6: =E7+E8 -> 128326 | F6: =F7+F8 -> 130768 | G6: =G7+G8 -> 150695 | H6: =H7+H8 -> 125362 | I6: =I7+I8 -> 134742 | J6: =J7+J8 -> 127840 | ... U6: =U7+U8 -> 126654
A7: Licenças | B7: License | C7: 58068 | D7: 45732 | E7: 50784 | F7: 53769 | G7: 79385 | H7: 44210 | I7: 51401 | J7: 49367 | K7: 80409 | L7: 48627 | M7: 52576 | N7: 58168 | O7: 76869 | P7: 46755 | Q7: 48932 | R7: 46307 | S7: 67655 | T7: 42415 | U7: 40646
A8: Serviços | B8: Services | C8: 66712 | D8: 72794 | E8: 77542 | F8: 76999 | G8: 71310 | H8: 81152 | I8: 83341 | J8: 78473 | K8: 76093 | L8: 89436 | M8: 94808 | N8: 87369 | O8: 82391 | P8: 88473 | Q8: 85010 | R8: 90389 | S8: 80191 | T8: 86016 | U8: 86008
A9: Custos | B9: Costs | C9: -175325 | D9: -186925 | E9: -195804 | F9: -210201 | G9: -220630 | H9: -229686 | I9: -245051 | J9: -251675 | K9: -251965 | L9: -254841 | M9: -281975 | N9: -292296 | O9: -301244 | P9: -323690 | Q9: -337260 | R9: -348424.33 | S9: -358097 | T9: -375913 | U9: -379155
A10: Lucro Bruto Ajustado | B10: Adjusted Gross Profit | C10: =C9+C4 -> 478496 | D10: =D9+D4 -> 485923 | E10: =E9+E4 -> 516489 | F10: =F9+F4 -> 543852 | G10: =G9+G4 -> 598829 | H10: =H9+H4 -> 601285 | I10: =I9+I4 -> 638472 | J10: =J9+J4 -> 656657 | ... U10: =U9+U4 -> 1014251
A11: Margem Bruta Ajustada | B11: Adjusted Gross Margin | C11: =C10/C4 -> 0.73184557 | D11: =D10/D4 -> 0.72218837 | E11: =E10/E4 -> 0.7251075 | F11: =F10/F4 -> 0.72123843 | G11: =G10/G4 -> 0.73076139 | H11: =H10/H4 -> 0.72359324 | I11: =I10/I4 -> 0.72264333 | J11: =J10/J4 -> 0.7229262 | ... U11: =U10/U4 -> 0.72789338
A12: Pesquisa e Desenvolvimento | B12: Research and Development | C12: -113064 | D12: -119466 | E12: -123470 | F12: -135390 | G12: -140915 | H12: -145620 | I12: -152136 | J12: -163174 | K12: -167399 | L12: -168205 | M12: -169404 | N12: -182290 | O12: -183854 | P12: -187569 | Q12: -195148 | R12: -201698 | S12: -207458 | T12: -222278 | U12: -234667
A13: Provisão para Perda Esperada | B13: Provision for Expected Credit Losses | C13: -4995 | D13: -4622 | E13: -6597 | F13: -2418 | G13: -6573 | H13: -4708 | I13: -7095 | J13: -3628 | K13: -5990 | L13: -8441 | M13: -7693 | N13: -6174 | O13: -10176 | P13: -12165 | Q13: -9114 | R13: -13385 | S13: -13649 | T13: -11299 | U13: -11825
A14: Despesas Comerciais e de Marketing | B14: Sales and Marketing Expenses | C14: -121690 | D14: -124685 | E14: -137011 | F14: -139253 | G14: -155199 | H14: -159047 | I14: -163866 | J14: -167254 | K14: -184294 | L14: -201382 | M14: -202688 | N14: -217888 | O14: -218647 | P14: -228213 | Q14: -230469 | R14: -239723 | S14: -258545 | T14: -273648 | U14: -267582
A15: Despesas Gerais e Administrativas | B15: General and Administrative Expenses | C15: -53998 | D15: -58031 | E15: -57967 | F15: -58674 | G15: -67608 | H15: -73008 | I15: -75490 | J15: -85344 | K15: -76507 | L15: -76941 | M15: -80928 | N15: -86166 | O15: -88176 | P15: -96065 | Q15: -93399 | R15: -99076 | S15: -97727 | T15: -98881 | U15: -110485
A16: Provisão para Contingências | B16: Provision for Contingencies | C16: -9086 | D16: -4803 | E16: -10615 | F16: -7330 | G16: -10936 | H16: -2650 | I16: -5497 | J16: -12870 | K16: -175 | L16: -7118 | M16: -3479 | N16: -9286 | O16: -244 | P16: -5799 | Q16: -4535 | R16: -9864 | S16: -13461 | T16: -2091 | U16: -8670
A17: Outras Receitas Operacionais Líquidas | B17: Other Net Revenues (Expenses) | C17: 1381 | D17: 582 | E17: 2862 | F17: 1641 | G17: -434 | H17: 983 | I17: 865 | J17: 3214 | K17: 1168 | L17: 1103 | M17: 1304 | N17: 3579 | O17: 2539 | P17: 4258 | Q17: 2791 | R17: 6553 | S17: 1655 | T17: 2156 | U17: 3460
A18: EBITDA Ajustado de Gestão | B18: Management Adjusted EBITDA | C18: =C10+SUM(C12:C13,C14:C17) -> 177044 | D18: =D10+SUM(D12:D13,D14:D17) -> 174898 | E18: =E10+SUM(E12:E13,E14:E17) -> 183691 | F18: =F10+SUM(F12:F13,F14:F17) -> 202428 | G18: =G10+SUM(G12:G13,G14:G17) -> 217164 | H18: =H10+SUM(H12:H13,H14:H17) -> 217235 | I18: =I10+SUM(I12:I13,I14:I17) -> 235253 | J18: =J10+SUM(J12:J13,J14:J17) -> 227601 | ... U18: =U10+SUM(U12:U13,U14:U17) -> 384482
A19: % EBITDA Ajustado de Gestão | B19: % Management Adjusted EBITDA | C19: =C18/C$4 -> 0.27078359 | D19: =D18/D$4 -> 0.25993687 | E19: =E18/E$4 -> 0.25788685 | F19: =F18/F$4 -> 0.26845328 | G19: =G18/G$4 -> 0.26500899 | H19: =H18/H$4 -> 0.26142308 | I19: =I18/I$4 -> 0.26626698 | J19: =J18/J$4 -> 0.25057028 | ... U19: =U18/U$4 -> 0.27592963
A20: Itens Extraordinários | B20: Extraordinary Items | C20: =SUM(C21:C29) -> -1972 | D20: =SUM(D21:D29) -> 3738 | E20: =SUM(E21:E29) -> -1447 | F20: =SUM(F21:F29) -> -8643 | G20: =SUM(G21:G29) -> -28178 | H20: =SUM(H21:H29) -> 13788 | I20: =SUM(I21:I29) -> -5278 | J20: =SUM(J21:J29) -> -10145 | ... U20: =SUM(U21:U29) -> -6188
A21: Custos com lay-offs | B21: Extraordinary Layoffs Costs | C21: 0 | D21: 0 | E21: 0 | F21: 0 | G21: 0 | H21: 0 | I21: 0 | J21: 0 | K21: 0 | L21: 0 | M21: 0 | N21: 0 | O21: 0 | P21: 0 | Q21: 0 | R21: 0 | S21: 0 | T21: 0 | U21: 0
A22: Provisões - Não Caixa | B22: Provision Adjustment - Non Cash | C22: 0 | D22: 0 | E22: 0 | F22: 0 | G22: 0 | H22: 0 | I22: 0 | J22: 0 | K22: 0 | L22: 0 | M22: 0 | N22: 0 | O22: 0 | P22: 0 | Q22: 0 | R22: 0 | S22: 0 | T22: 0 | U22: 0
A23: Indenização por Rescisão de Contrato | B23: Indemnity for Termination of Contract | C23: 0 | D23: 0 | E23: 0 | F23: 0 | G23: 0 | H23: 0 | I23: 0 | J23: 0 | K23: 0 | L23: 0 | M23: 0 | N23: 0 | O23: 0 | P23: 0 | Q23: 0 | R23: 0 | S23: 0 | T23: 0 | U23: 0
A24: Ajuste de M&A a Valor Justo | B24: M&A Adjustment at Fair Value | C24: 0 | D24: 834 | E24: 0 | F24: -18943 | G24: -24913 | H24: -1158 | I24: 0 | J24: -498 | K24: -1201 | L24: -5064 | M24: -8256 | N24: 1581 | O24: -14035 | P24: -1551 | Q24: 0 | R24: 7616 | S24: -13486 | T24: 2879 | U24: 0
A25: Perda (Ganho) na Baixa de Ativos | B25: Lost (Earn) in Investment Sale | C25: 0 | D25: 0 | E25: 1156 | F25: 0 | G25: 0 | H25: 0 | I25: 0 | J25: -4689 | K25: 0 | L25: 0 | M25: 0 | N25: 0 | O25: 5892 | P25: 0 | Q25: 8599 | R25: -7333 | S25: -2411 | T25: -1759 | U25: 0
A26: Gastos com Transações de M&A | B26: Expenses with M&A Transactions | C26: -1972 | D26: -5814 | E26: -2603 | F26: -178 | G26: -3265 | H26: -2657 | I26: -5278 | J26: -3963 | K26: -1270 | L26: -1364 | M26: -1492 | N26: -5711 | O26: -2969 | P26: -3935 | Q26: -3101 | R26: -2757 | S26: -1880 | T26: -1222 | U26: -6220
A27: Crédito Tributário | B27: Tax Credit | C27: 0 | D27: 8718 | E27: 0 | F27: 10478 | G27: 0 | H27: 17603 | I27: 0 | J27: -995 | K27: 0 | L27: -863 | M27: 233 | N27: 0 | O27: 0 | P27: 0 | Q27: 0 | R27: 0 | S27: 0 | T27: 0 | U27: 0
A28: Ajuste Extraord. Reestruturação Operacional | B28: Extraord. Adj. - Operatl. Restructuring | C28: 0 | D28: 0 | E28: 0 | F28: 0 | G28: 0 | H28: 0 | I28: 0 | J28: 0 | K28: -3094 | L28: -7347 | M28: -53 | N28: -2046 | O28: -4057 | P28: -60 | Q28: 451 | R28: -4113 | S28: -575 | T28: -3066 | U28: 32
A29: Reoneração da Folha de Pagamento | B29: Adj. - Payroll Tax Surcharge | C29: 0 | D29: 0 | E29: 0 | F29: 0 | G29: 0 | H29: 0 | I29: 0 | J29: 0 | K29: 0 | L29: 0 | M29: 0 | N29: 0 | O29: 0 | P29: 0 | Q29: 0 | R29: -13948.67 | S29: 0 | T29: 0 | U29: 0
A30: EBITDA Gestão | B30: Management EBITDA | C30: =C18+C20 -> 175072 | D30: =D18+D20 -> 178636 | E30: =E18+E20 -> 182244 | F30: =F18+F20 -> 193785 | G30: =G18+G20 -> 188986 | H30: =H18+H20 -> 231023 | I30: =I18+I20 -> 229975 | J30: =J18+J20 -> 217456 | ... U30: =U18+U20 -> 378294
A31: % EBITDA Gestão | B31: % Management EBITDA | C31: =C30/C$4 -> 0.26776748 | D31: =D30/D$4 -> 0.26549235 | E31: =E30/E$4 -> 0.25585539 | F31: =F30/F$4 -> 0.25699122 | G31: =G30/G$4 -> 0.23062289 | H31: =H30/H$4 -> 0.27801572 | I31: =I30/I$4 -> 0.26029317 | J31: =J30/J$4 -> 0.23940145 | ... U31: =U30/U$4 -> 0.27148871
A33: Resultado da RD Station | B33: RD Station Result
A34: Receita Líquida | B34: Net Revenue | C34: =C35+C38 -> 642 | D34: =D35+D38 -> 19299 | E34: =E35+E38 -> 58683 | F34: =F35+F38 -> 63722 | G34: =G35+G38 -> 66345 | H34: =H35+H38 -> 71582 | I34: =I35+I38 -> 78397 | J34: =J35+J38 -> 84231 | ... U34: =U35+U38 -> 161850
A35: Recorrente | B35: Recurring | C35: =C36+C37 -> 777 | D35: =D36+D37 -> 18887 | E35: =E36+E37 -> 57241 | F35: =F36+F37 -> 61991 | G35: =G36+G37 -> 65488 | H35: =H36+H37 -> 70459 | I35: =I36+I37 -> 77073 | J35: =J36+J37 -> 82942 | ... U35: =U36+U37 -> 155796
A36: SaaS | B36: SaaS | C36: 777 | D36: 18887 | E36: 57241 | F36: 61991 | G36: 65488 | H36: 70459 | I36: 76982 | J36: 82841 | K36: 85673 | L36: 93786 | M36: 107377 | N36: 116956 | O36: 121803 | P36: 126691 | Q36: 131238 | R36: 136283 | S36: 137795 | T36: 144781 | U36: 150884
A37: Transacional | B37: Transactional | C37: 0 | D37: 0 | E37: 0 | F37: 0 | G37: 0 | H37: 0 | I37: 91 | J37: 101 | K37: 1111 | L37: 1372 | M37: 1083 | N37: 307 | O37: 1724 | P37: 2578 | Q37: 3220 | R37: 3830 | S37: 4783 | T37: 6403 | U37: 4912
A38: Não Recorrente | B38: Non Recurring | C38: -135 | D38: 412 | E38: 1442 | F38: 1731 | G38: 857 | H38: 1123 | I38: 1324 | J38: 1289 | K38: 1279 | L38: 2925 | M38: 3729 | N38: 4074 | O38: 4026 | P38: 4376 | Q38: 5837 | R38: 5753 | S38: 6288 | T38: 4732 | U38: 6054
A39: Custos | B39: Costs | C39: -62 | D39: -4144 | E39: -14156 | F39: -16018 | G39: -16465 | H39: -16555 | I39: -17876 | J39: -19022 | K39: -20033 | L39: -22179 | M39: -25391 | N39: -27557 | O39: -29428 | P39: -32072 | Q39: -32851 | R39: -33584.67 | S39: -37652 | T39: -39134 | U39: -40254
A40: Lucro Bruto Ajustado | B40: Adjusted Gross Profit | C40: =C39+C34 -> 580 | D40: =D39+D34 -> 15155 | E40: =E39+E34 -> 44527 | F40: =F39+F34 -> 47704 | G40: =G39+G34 -> 49880 | H40: =H39+H34 -> 55027 | I40: =I39+I34 -> 60521 | J40: =J39+J34 -> 65209 | ... U40: =U39+U34 -> 121596
A41: Margem Bruta Ajustada | B41: Adjusted Gross Margin | C41: =C40/C34 -> 0.90342679 | D41: =D40/D34 -> 0.78527385 | E41: =E40/E34 -> 0.75877171 | F41: =F40/F34 -> 0.74862685 | G41: =G40/G34 -> 0.75182757 | H41: =H40/H34 -> 0.76872677 | I41: =I40/I34 -> 0.77198107 | J41: =J40/J34 -> 0.77416866 | ... U41: =U40/U34 -> 0.75128823
...

Sheet GAAP-Consolidated-BS
A1: PORTUGUÊS | B1: ENGLISH
A2: Balanço Patrimonial (GAAP) (R$ mil) | B2: GAAP Balance Sheet (R$ thousand) | C2: 1Q18 | D2: 2Q18 | E2: 3Q18 | F2: 4Q18 | G2: 1Q19 | H2: 2Q19 | I2: 3Q19 | J2: 4Q19 | K2: 1Q20 | L2: 2Q20 | M2: 3Q20 | N2: 4Q20 | O2: 1Q21 | P2: 2Q21 | Q2: 3Q21 | R2: 4Q21 | S2: 1Q22 | T2: 2Q22 | U2: 3Q22 | V2: 4Q22 | W2: 1Q23 | X2: 2Q23 | Y2: 3Q23 | Z2: 4Q23 | AA2: 1Q24 | AB2: 2Q24 | AC2: 3Q24 | AD2: 4Q24 | AE2: 1Q25 | AF2: 2Q25 | AG2: 3Q25
A4: ATIVO | B4: ASSETS | C4: =C5+C16 -> 2465242 | D4: =D5+D16 -> 2470229 | E4: =E5+E16 -> 2492641 | F4: =F5+F16 -> 2391277 | G4: =G5+G16 -> 2585845 | H4: =H5+H16 -> 3637843 | I4: =I5+I16 -> 3598169 | J4: =J5+J16 -> 3535927 | ... AG4: =AG5+AG16 -> 9219852
A5: Circulante | B5: Current assets | C5: =SUM(C6:C14) -> 1038781 | D5: =SUM(D6:D14) -> 1062090 | E5: =SUM(E6:E14) -> 1084241 | F5: =SUM(F6:F14) -> 1020134 | G5: =SUM(G6:G14) -> 1026741 | H5: =SUM(H6:H14) -> 2092456 | I5: =SUM(I6:I14) -> 2044020 | J5: =SUM(J6:J14) -> 2004275 | ... AG5: =SUM(AG6:AG14) -> 3145240
A6: Caixa e Equivalentes de Caixa | B6: Cash and Cash Equivalents | C6: 380705 | D6: 394462 | E6: 449606 | F6: 452799 | G6: 423658 | H6: 1494584 | I6: 1487702 | J6: 1538156 | K6: 1365366 | L6: 1263927 | M6: 999800 | N6: 1011638 | O6: 886108 | P6: 645664 | Q6: 2073866 | R6: 2735764 | S6: 2704890 | T6: 2567054 | U6: 2541052 | V6: 2735765 | W6: 2536064 | X6: 2720311 | Y6: 3056726 | Z6: 3129162 | AA6: 2548116 | AB6: 2205225 | AC6: 2154825 | AD6: 1942162 | AE6: 1943040 | AF6: 2094240 | AG6: 2005729
A7: Contas a Receber de Clientes | B7: Trade Receivables | C7: 535212 | D7: 542206 | E7: 536052 | F7: 504056 | G7: 484546 | H7: 476132 | I7: 470151 | J7: 453118 | K7: 460210 | L7: 514723 | M7: 598932 | N7: 630361 | O7: 474786 | P7: 502133 | Q7: 522425 | R7: 500958 | S7: 546459 | T7: 586998 | U7: 595520 | V7: 538199 | W7: 563766 | X7: 595326 | Y7: 617008 | Z7: 600731 | AA7: 642398 | AB7: 643537 | AC7: 647773 | AD7: 625678 | AE7: 714209 | AF7: 734666 | AG7: 736081
A8: Provisão para Perdas Esperadas | B8: Provision for Expected Credit Losses | C8: -107286 | D8: -110472 | E8: -112497 | F8: -118518 | G8: -117040 | H8: -110476 | I8: -109202 | J8: -102123 | K8: -89424 | L8: -90547 | M8: -81506 | N8: -76643 | O8: -79467 | P8: -79615 | Q8: -83918 | R8: -83383 | S8: -69278 | T8: -74831 | U8: -60966 | V8: -62551 | W8: -57532 | X8: -65549 | Y8: -59968 | Z8: -62203 | AA8: -61741 | AB8: -59316 | AC8: -65848 | AD8: -62350 | AE8: -73106 | AF8: -68298 | AG8: -67467
A9: Aplicações Financeiras | B9: Financial Investments | C9: 0 | D9: 0 | E9: 0 | F9: 0 | G9: 0 | H9: 0 | I9: 0 | J9: 0 | K9: 0 | L9: 47348 | M9: 53862 | N9: 161327 | O9: 0 | P9: 0 | Q9: 0 | R9: 0 | S9: 4273 | T9: 4382 | U9: 0 | V9: 0 | W9: 0 | X9: 0 | Y9: 0 | Z9: 0 | AA9: 0 | AB9: 0 | AC9: 0 | AD9: 0 | AE9: 0 | AF9: 0 | AG9: 0
A10: Estoques | B10: Inventory | C10: 41217 | D10: 37647 | E10: 35584 | F10: 41531 | G10: 0 | H10: 0 | I10: 0 | J10: 0 | K10: 0 | L10: 0 | M10: 0 | N10: 0 | O10: 0 | P10: 0 | Q10: 0 | R10: 0 | S10: 0 | T10: 0 | U10: 0 | V10: 0 | W10: 0 | X10: 0 | Y10: 0 | Z10: 0 | AA10: 0 | AB10: 0 | AC10: 0 | AD10: 0 | AE10: 0 | AF10: 0 | AG10: 0
A11: Tributos Correntes a Recuperar | B11: Recoverable Taxes | C11: 86623 | D11: 81224 | E11: 62777 | F11: 38817 | G11: 33674 | H11: 27877 | I11: 12161 | J11: 29662 | K11: 39277 | L11: 18071 | M11: 22384 | N11: 38092 | O11: 29700 | P11: 42302 | Q11: 37209 | R11: 67553 | S11: 78306 | T11: 74013 | U11: 71953 | V11: 87932 | W11: 96001 | X11: 74849 | Y11: 39165 | Z11: 87838 | AA11: 91170 | AB11: 73785 | AC11: 80289 | AD11: 83519 | AE11: 100935 | AF11: 93917 | AG11: 77107
A12: Garantias de Investimentos | B12: Escrow Account | C12: 49882 | D12: 49398 | E12: 46934 | F12: 44909 | G12: 44711 | H12: 45203 | I12: 26188 | J12: 25278 | K12: 10204 | L12: 10260 | M12: 10307 | N12: 10012 | O12: 9718 | P12: 9067 | Q12: 9191 | R12: 9341 | S12: 9593 | T12: 9811 | U12: 11652 | V12: 10391 | W12: 12707 | X12: 12206 | Y12: 13150 | Z12: 13175 | AA12: 13754 | AB12: 19575 | AC12: 13675 | AD12: 13974 | AE12: 14339 | AF12: 19182 | AG12: 46057
A13: Outros Ativos | B13: Othe Assets | C13: 52428 | D13: 67625 | E13: 65785 | F13: 56540 | G13: 69280 | H13: 61930 | I13: 58006 | J13: 60184 | K13: 74344 | L13: 81585 | M13: 64164 | N13: 45903 | O13: 59021 | P13: 91113 | Q13: 99715 | R13: 107739 | S13: 109519 | T13: 149379 | U13: 152408 | V13: 96447 | W13: 117905 | X13: 175915 | Y13: 183842 | Z13: 137595 | AA13: 141752 | AB13: 188107 | AC13: 227792 | AD13: 160575 | AE13: 165450 | AF13: 238249 | AG13: 289915
A14: Ativos Mantidos Para Venda | B14: Assets For Sale | C14: 0 | D14: 0 | E14: 0 | F14: 0 | G14: 87912 | H14: 97206 | I14: 99014 | J14: 0 | K14: 0 | L14: 0 | M14: 0 | N14: 0 | O14: 2230408 | P14: 2475620 | Q14: 2799755 | R14: 2641217 | S14: 2605828 | T14: 2758444 | U14: 2960010 | V14: 2823978 | W14: 2589975 | X14: 2905717 | Y14: 0 | Z14: 0 | AA14: 0 | AB14: 0 | AC14: 0 | AD14: 0 | AE14: 56842 | AF14: 57401 | AG14: 57818
A16: Não circulante | B16: Non-current assets | C16: =C17+SUM(C27:C29) -> 1426461 | D16: =D17+SUM(D27:D29) -> 1408139 | E16: =E17+SUM(E27:E29) -> 1408400 | F16: =F17+SUM(F27:F29) -> 1371143 | G16: =G17+SUM(G27:G29) -> 1559104 | H16: =H17+SUM(H27:H29) -> 1545387 | I16: =I17+SUM(I27:I29) -> 1554149 | J16: =J17+SUM(J27:J29) -> 1531652 | ... AG16: =AG17+SUM(AG27:AG29) -> 6074612
A17: Realizável a longo prazo | B17: Long-term assets | C17: =SUM(C18:C25) -> 296261 | D17: =SUM(D18:D25) -> 291007 | E17: =SUM(E18:E25) -> 289340 | F17: =SUM(F18:F25) -> 312060 | G17: =SUM(G18:G25) -> 299297 | H17: =SUM(H18:H25) -> 309193 | I17: =SUM(I18:I25) -> 345272 | J17: =SUM(J18:J25) -> 328403 | ... AG17: =SUM(AG18:AG25) -> 858902
A18: Contas a Receber de Clientes | B18: Trade Receivables | C18: 31733 | D18: 24860 | E18: 21777 | F18: 19890 | G18: 21672 | H18: 33544 | I18: 36401 | J18: 31627 | K18: 27578 | L18: 39327 | M18: 57679 | N18: 64012 | O18: 55988 | P18: 60881 | Q18: 60254 | R18: 64943 | S18: 56428 | T18: 53515 | U18: 47066 | V18: 38419 | W18: 31655 | X18: 22560 | Y18: 19030 | Z18: 16496 | AA18: 16664 | AB18: 19747 | AC18: 16519 | AD18: 13796 | AE18: 14492 | AF18: 15138 | AG18: 17897
A19: IR e CSLL Diferidos | B19: Deferred Tax Assets | C19: 97839 | D19: 85222 | E19: 80735 | F19: 125124 | G19: 110182 | H19: 104499 | I19: 106412 | J19: 100380 | K19: 78803 | L19: 87059 | M19: 96481 | N19: 100535 | O19: 94718 | P19: 84883 | Q19: 94881 | R19: 107000 | S19: 112661 | T19: 101145 | U19: 96046 | V19: 119048 | W19: 116865 | X19: 117297 | Y19: 123031 | Z19: 147426 | AA19: 138580 | AB19: 136133 | AC19: 231218 | AD19: 253511 | AE19: 256100 | AF19: 245119 | AG19: 243444
A20: Depósitos Judiciais | B20: Judicial Deposits | C20: 60190 | D20: 63863 | E20: 61873 | F20: 65965 | G20: 70399 | H20: 69702 | I20: 73675 | J20: 65059 | K20: 51484 | L20: 50094 | M20: 48789 | N20: 43972 | O20: 44324 | P20: 43617 | Q20: 42157 | R20: 29236 | S20: 28814 | T20: 32129 | U20: 32622 | V20: 34244 | W20: 37644 | X20: 39283 | Y20: 39673 | Z20: 33832 | AA20: 32244 | AB20: 32758 | AC20: 31928 | AD20: 28373 | AE20: 32411 | AF20: 29206 | AG20: 28404
A21: Crédito com Empresas Ligadas | B21: Credit with Related Parties | C21: 0 | D21: 0 | E21: 0 | F21: 0 | G21: 0 | H21: 0 | I21: 0 | J21: 0 | K21: 0 | L21: 0 | M21: 0 | N21: 0 | O21: 0 | P21: 0 | Q21: 0 | R21: 0 | S21: 0 | T21: 0 | U21: 678 | V21: 905 | W21: 1134 | X21: 7214 | Y21: 2507 | Z21: 3787 | AA21: 4997 | AB21: 4876 | AC21: 5231 | AD21: 5050 | AE21: 5817 | AF21: 4746 | AG21: 4739
A22: Tributos a Recuperar | B22: Recoverable taxes | C22: 21752 | D22: 21677 | E22: 21160 | F22: 236 | G22: 207 | H22: 0 | I22: 0 | J22: 0 | K22: 0 | L22: 8139 | M22: 8024 | N22: 0 | O22: 0 | P22: 0 | Q22: 0 | R22: 0 | S22: 0 | T22: 17752 | U22: 18077 | V22: 14216 | W22: 8091 | X22: 4092 | Y22: 1191 | Z22: 0 | AA22: 0 | AB22: 0 | AC22: 0 | AD22: 0 | AE22: 0 | AF22: 0 | AG22: 0
A23: Garantias de Investimentos | B23: Escrow Account | C23: 0 | D23: 0 | E23: 6464 | F23: 5334 | G23: 4368 | H23: 3735 | I23: 2455 | J23: 1987 | K23: 1630 | L23: 1347 | M23: 1141 | N23: 1116 | O23: 0 | P23: 34388 | Q23: 34857 | R23: 35427 | S23: 36386 | T23: 31288 | U23: 43978 | V23: 73766 | W23: 77066 | X23: 81709 | Y23: 114129 | Z23: 116759 | AA23: 178231 | AB23: 179074 | AC23: 181564 | AD23: 188845 | AE23: 182538 | AF23: 183976 | AG23: 192747
A24: Ativos Financeiros | B24: Investiments at Fair Value | C24: 57913 | D24: 67192 | E24: 69772 | F24: 69171 | G24: 69562 | H24: 68411 | I24: 74341 | J24: 71955 | K24: 92805 | L24: 97756 | M24: 100696 | N24: 92770 | O24: 101706 | P24: 89297 | Q24: 97102 | R24: 99621 | S24: 84577 | T24: 96516 | U24: 107067 | V24: 111231 | W24: 108091 | X24: 105384 | Y24: 110891 | Z24: 127483 | AA24: 140657 | AB24: 148965 | AC24: 163523 | AD24: 179830 | AE24: 193669 | AF24: 196743 | AG24: 213101
A25: Outros Ativos | B25: Othe Assets | C25: 26834 | D25: 28193 | E25: 27559 | F25: 26340 | G25: 22907 | H25: 29302 | I25: 51988 | J25: 57395 | K25: 65203 | L25: 60161 | M25: 59154 | N25: 57928 | O25: 61481 | P25: 78855 | Q25: 97814 | R25: 86703 | S25: 81367 | T25: 73645 | U25: 70506 | V25: 71563 | W25: 71662 | X25: 61847 | Y25: 57318 | Z25: 68699 | AA25: 72900 | AB25: 79063 | AC25: 103003 | AD25: 116522 | AE25: 135362 | AF25: 166598 | AG25: 158570
A27: Investimentos | B27: Investments | C27: 2407 | D27: 2589 | E27: 2551 | F27: 3129 | G27: 3054 | H27: 3033 | I27: 3204 | J27: 3120 | K27: 3239 | L27: 3464 | M27: 3402 | N27: 3476 | O27: 3707 | P27: 2797 | Q27: 2982 | R27: 3075 | S27: 2695 | T27: 2943 | U27: 3036 | V27: 0 | W27: 0 | X27: 0 | Y27: 324573 | Z27: 323367 | AA27: 319106 | AB27: 315545 | AC27: 317603 | AD27: 321796 | AE27: 324770 | AF27: 324923 | AG27: 314411
A28: Imobilizado | B28: Property, Plant and Equipment | C28: 185986 | D28: 186075 | E28: 189393 | F28: 198826 | G28: 416837 | H28: 402844 | I28: 388057 | J28: 389432 | K28: 393959 | L28: 387229 | M28: 378120 | N28: 364447 | O28: 388788 | P28: 385111 | Q28: 387470 | R28: 398496 | S28: 407399 | T28: 405241 | U28: 415777 | V28: 416875 | W28: 422161 | X28: 423663 | Y28: 424418 | Z28: 413486 | AA28: 405689 | AB28: 400429 | AC28: 397524 | AD28: 399215 | AE28: 418894 | AF28: 423074 | AG28: 456734
A29: Intangível | B29: Intangible Assets | C29: 941807 | D29: 928468 | E29: 927116 | F29: 857128 | G29: 839916 | H29: 830317 | I29: 817616 | J29: 810697 | K29: 1031418 | L29: 1590955 | M29: 1567313 | N29: 1586177 | O29: 1074309 | P29: 3137086 | Q29: 3149528 | R29: 3141338 | S29: 3283360 | T29: 3329185 | U29: 3492907 | V29: 3505765 | W29: 3502339 | X29: 3641474 | Y29: 3688497 | Z29: 3671227 | AA29: 4339314 | AB29: 4315393 | AC29: 4273733 | AD29: 4261225 | AE29: 4199832 | AF29: 4203673 | AG29: 4444565
A31: PASSIVO | B31: LIABILITIES | C31: =C32+C46+C58 -> 2465242 | D31: =D32+D46+D58 -> 2470229 | E31: =E32+E46+E58 -> 2492641 | F31: =F32+F46+F58 -> 2391277 | G31: =G32+G46+G58 -> 2585845 | H31: =H32+H46+H58 -> 3637843 | I31: =I32+I46+I58 -> 3598169 | J31: =J32+J46+J58 -> 3535927 | ... AG31: =AG32+AG46+AG58 -> 9219852
A32: Circulante | B32: Current liabilities | C32: =SUM(C33:C44) -> 634244 | D32: =SUM(D33:D44) -> 619774 | E32: =SUM(E33:E44) -> 746985 | F32: =SUM(F33:F44) -> 709612 | G32: =SUM(G33:G44) -> 706705 | H32: =SUM(H33:H44) -> 666765 | I32: =SUM(I33:I44) -> 768434 | J32: =SUM(J33:J44) -> 705552 | ... AG32: =SUM(AG33:AG44) -> 1339676
A33: Obrigações Sociais e Trabalhistas | B33: Labor Liabilities | C33: 147531 | D33: 169429 | E33: 192050 | F33: 174874 | G33: 168334 | H33: 190874 | I33: 217227 | J33: 193472 | K33: 190583 | L33: 235415 | M33: 238636 | N33: 211603 | O33: 207906 | P33: 319693 | Q33: 287922 | R33: 273974 | S33: 278175 | T33: 353390 | U33: 349392 | V33: 317684 | W33: 321109 | X33: 406082 | Y33: 414207 | Z33: 375960 | AA33: 407683 | AB33: 478996 | AC33: 473272 | AD33: 438679 | AE33: 442831 | AF33: 547042 | AG33: 544748
A34: Obrigações fiscais | B34: Taxes and Contributions Liabilities | C34: 40465 | D34: 39562 | E34: 41700 | F34: 47466 | G34: 44757 | H34: 53036 | I34: 55511 | J34: 55203 | K34: 53701 | L34: 99969 | M34: 89580 | N34: 74558 | O34: 63785 | P34: 68338 | Q34: 69031 | R34: 73605 | S34: 71857 | T34: 90197 | U34: 87792 | V34: 95042 | W34: 94422 | X34: 97955 | Y34: 110232 | Z34: 107427 | AA34: 116237 | AB34: 119837 | AC34: 113945 | AD34: 122612 | AE34: 121373 | AF34: 131815 | AG34: 134462
A35: Empréstimos e Financiamentos | B35: Loans and Financing | C35: 180979 | D35: 181079 | E35: 181090 | F35: 152927 | G35: 110559 | H35: 67803 | I35: 23333 | J35: 6363 | K35: 3649 | L35: 11071 | M35: 0 | N35: 101525 | O35: 0 | P35: 0 | Q35: 0 | R35: 0 | S35: 0 | T35: 0 | U35: 343 | V35: 170 | W35: 50 | X35: 0 | Y35: 32084 | Z35: 32083 | AA35: 1708 | AB35: 0 | AC35: 0 | AD35: 0 | AE35: 0 | AF35: 0 | AG35: 0
A36: Financiamento por Arrendamento | B36: Lease Liabilities | C36: 18587 | D36: 17834 | E36: 15401 | F36: 13227 | G36: 68150 | H36: 62717 | I36: 49910 | J36: 49260 | K36: 47588 | L36: 47323 | M36: 46785 | N36: 45281 | O36: 53496 | P36: 51429 | Q36: 51197 | R36: 51536 | S36: 58131 | T36: 56672 | U36: 56549 | V36: 57285 | W36: 57636 | X36: 59469 | Y36: 58414 | Z36: 58618 | AA36: 59838 | AB36: 57525 | AC36: 58195 | AD36: 58133 | AE36: 60100 | AF36: 67315 | AG36: 70654
A37: Debêntures | B37: Debentures | C37: 356 | D37: 3717 | E37: 72035 | F37: 77319 | G37: 76238 | H37: 81964 | I37: 200288 | J37: 202973 | K37: 200257 | L37: 403787 | M37: 0 | N37: 0 | O37: 0 | P37: 2993 | Q37: 27365 | R37: 385988 | S37: 430872 | T37: 518245 | U37: 5151 | V37: 58701 | W37: 8728 | X37: 61331 | Y37: 7327 | Z37: 55208 | AA37: 10279 | AB37: 48594 | AC37: 18480 | AD37: 62845 | AE37: 33383 | AF37: 88182 | AG37: 40692
A38: Fornecedores | B38: Trade and Other Payables | C38: 91276 | D38: 95745 | E38: 101543 | F38: 113907 | G38: 70560 | H38: 61544 | I38: 55512 | J38: 63821 | K38: 66238 | L38: 75153 | M38: 91360 | N38: 99109 | O38: 70988 | P38: 102242 | Q38: 108081 | R38: 105376 | S38: 102829 | T38: 102010 | U38: 118006 | V38: 128647 | W38: 112005 | X38: 200244 | Y38: 133117 | Z38: 155266 | AA38: 171433 | AB38: 194614 | AC38: 170444 | AD38: 211971 | AE38: 232230 | AF38: 224300 | AG38: 209380
A39: Comissões a Pagar | B39: Commissions Payable | C39: 45020 | D39: 42231 | E39: 41376 | F39: 43166 | G39: 47429 | H39: 43217 | I39: 44136 | J39: 46035 | K39: 52649 | L39: 47255 | M39: 53831 | N39: 53795 | O39: 60963 | P39: 60568 | Q39: 58838 | R39: 58158 | S39: 67516 | T39: 62330 | U39: 62406 | V39: 65518 | W39: 73849 | X39: 67997 | Y39: 64990 | Z39: 62610 | AA39: 61228 | AB39: 52412 | AC39: 63630 | AD39: 69126 | AE39: 60934 | AF39: 64475 | AG39: 69762
A40: Obrigações por Aquisição de Investimentos | B40: Accounts Payable from Acquisition of Subsidiaries | C40: 87986 | D40: 65641 | E40: 63177 | F40: 59597 | G40: 59398 | H40: 52479 | I40: 33464 | J40: 32554 | K40: 30717 | L40: 33891 | M40: 44174 | N40: 44781 | O40: 29400 | P40: 160230 | Q40: 136737 | R40: 153839 | S40: 95853 | T40: 48706 | U40: 59865 | V40: 52700 | W40: 96737 | X40: 315309 | Y40: 377285 | Z40: 421803 | AA40: 496198 | AB40: 238083 | AC40: 244932 | AD40: 115659 | AE40: 46348 | AF40: 43462 | AG40: 73859
A41: Dividendos e JCP a Pagar | B41: Dividends Payable | C41: 15972 | D41: 613 | E41: 31285 | F41: 13902 | G41: 12293 | H41: 768 | I41: 32828 | J41: 44579 | K41: 39705 | L41: 870 | M41: 36075 | N41: 57687 | O41: 51250 | P41: 1040 | Q41: 46388 | R41: 80153 | S41: 70895 | T41: 1191 | U41: 1270 | V41: 130363 | W41: 3316 | X41: 1432 | Y41: 1628 | Z41: 1781 | AA41: 1781 | AB41: 1781 | AC41: 1055 | AD41: 1222 | AE41: 83248 | AF41: 89324 | AG41: 89576
A42: Outros Passivos | B42: Other Liabilities | C42: 6072 | D42: 3923 | E42: 7328 | F42: 13227 | G42: 6778 | H42: 8800 | I42: 10485 | J42: 11292 | K42: 14546 | L42: 11927 | M42: 9836 | N42: 11592 | O42: 9263 | P42: 66689 | Q42: 83067 | R42: 86981 | S42: 96838 | T42: 114450 | U42: 127262 | V42: 66657 | W42: 80644 | X42: 86703 | Y42: 97882 | Z42: 77973 | AA42: 100887 | AB42: 88291 | AC42: 110038 | AD42: 63950 | AE42: 68302 | AF42: 77558 | AG42: 96720
A43: Repasse para Parceiros | B43: Transfer to Partners | C43: 0 | D43: 0 | E43: 0 | F43: 0 | G43: 0 | H43: 0 | I43: 0 | J43: 0 | K43: 0 | L43: 160843 | M43: 288733 | N43: 328817 | O43: 0 | P43: 0 | Q43: 0 | R43: 0 | S43: 0 | T43: 0 | U43: 0 | V43: 0 | W43: 0 | X43: 0 | Y43: 0 | Z43: 0 | AA43: 0 | AB43: 0 | AC43: 0 | AD43: 0 | AE43: 0 | AF43: 0 | AG43: 0
A44: Passivos Mantidos para Venda | B44: Liabilities for Sale | C44: 0 | D44: 0 | E44: 0 | F44: 0 | G44: 42209 | H44: 43563 | I44: 45740 | J44: 0 | K44: 0 | L44: 0 | M44: 0 | N44: 0 | O44: 1646270 | P44: 1893378 | Q44: 2217587 | R44: 2054172 | S44: 2027434 | T44: 2180375 | U44: 2335779 | V44: 2363599 | W44: 2135385 | X44: 2459248 | Y44: 0 | Z44: 0 | AA44: 0 | AB44: 0 | AC44: 0 | AD44: 0 | AE44: 9645 | AF44: 9846 | AG44: 9823
...

Sheet GAAP-Consolidated-CF
A1: PORTUGUÊS | B1: ENGLISH
A2: Fluxo de Caixa (GAAP) Trimestre (R$ mil) | B2: GAAP Cash Flow - Quarter (R$ thousand) | C2: 1Q21 | D2: 2Q21 | E2: 3Q21 | F2: 4Q21 | G2: 1Q22 | H2: 2Q22 | I2: 3Q22 | J2: 4Q22 | K2: 1Q23 | L2: 2Q23 | M2: 3Q23 | N2: 4Q23 | O2: 1Q24 | P2: 2Q24 | Q2: 3Q24 | R2: 4Q24 | S2: 1Q25 | T2: 2Q25 | U2: 3Q25
A3: Fluxo de caixa das atividades operacionais: | B3: Operating Cashflow
A4: Lucro antes Tributação Imp. Renda e Contrib. Social | B4: Net income before taxes | C4: 122504 | D4: 121660 | E4: 94696 | F4: 140665 | G4: 132469 | H4: 189882 | I4: 177883 | J4: 161361 | K4: 168275 | L4: 165177 | M4: 214521 | N4: 135313 | O4: 208406 | P4: 181505 | Q4: 230528 | R4: 204799 | S4: 258556 | T4: 242867 | U4: 310689
A6: Ajustes por: | B6: Adjustments:
A7: Depreciação e Amortização | B7: Depreciation and Amortization | C7: 44130 | D7: 44536 | E7: 55609 | F7: 54909 | G7: 57110 | H7: 58116 | I7: 59635 | J7: 61267 | K7: 62136 | L7: 75791 | M7: 71540 | N7: 73334 | O7: 73375 | P7: 84261 | Q7: 86775 | R7: 81508 | S7: 85427 | T7: 88969 | U7: 93714
A8: Pagamento Baseado em Ações | B8: Share-based Payments Expense | C8: 7115 | D8: 8053 | E8: 13967 | F8: 5478 | G8: 13739 | H8: 1563 | I8: 19217 | J8: 18611 | K8: 17346 | L8: 5441 | M8: 20454 | N8: 21083 | O8: 26045 | P8: -6533 | Q8: 21587 | R8: 4719 | S8: 12431 | T8: 14324 | U8: 28867
A9: Perda (Ganho) na Baixa de Ativos | B9: Losses on Disposal of Fixed Assets and Inv. | C9: -294 | D9: 310 | E9: 10383 | F9: -826 | G9: 210 | H9: -678 | I9: -1911 | J9: 880 | K9: 955 | L9: -266 | M9: -165 | N9: 880 | O9: -564 | P9: -6492 | Q9: -11127 | R9: 8487 | S9: 2295 | T9: 1677.6015 | U9: -1058
A10: Provisão para Perda Esperada | B10: Provision for Expected Credit Losses | C10: 5050 | D10: 4808 | E10: 8368 | F10: 2287 | G10: 7334 | H10: 5854 | I10: 8577 | J10: 5147 | K10: 7461 | L10: 10208 | M10: 10388 | N10: 8337 | O10: 13237 | P10: 16267 | Q10: 12871 | R10: 16252 | S10: 14576 | T10: 14038 | U10: 14330
A11: Equivalência Patrimonial | B11: Equity Pickup | C11: 0 | D11: 564 | E11: -38 | F11: 0 | G11: -7 | H11: 0 | I11: 0 | J11: 449 | K11: 0 | L11: 0 | M11: -4402 | N11: 1207 | O11: 4261 | P11: 3561 | Q11: -2058 | R11: -4193 | S11: -2974 | T11: -154 | U11: -7401
A12: Provisão (Reversão) para Contingências | B12: Provision for Contingencies, Net of Reversals | C12: 9086 | D12: 4804 | E12: 10614 | F12: 7330 | G12: 10936 | H12: 2690 | I12: 5498 | J12: 12870 | K12: 105 | L12: 7126 | M12: 3498 | N12: 12350 | O12: 429 | P12: 6041 | Q12: 4535 | R12: 9893 | S12: 13470 | T12: 2128 | U12: 13669
A13: Provisão (Reversão) de outras Obrig. e Outros | B13: Provision (Reversal) for Other Obligations | C13: 0 | D13: 0 | E13: -1401 | F13: 18943 | G13: 24913 | H13: -1950 | I13: 0 | J13: 5292 | K13: 21607 | L13: 5576 | M13: 8023 | N13: 35454 | O13: 14035 | P13: -15637 | Q13: -20143 | R13: 16533 | S13: 11169 | T13: 5289 | U13: 0
A14: Juros e Variação Cambiais e Monetárias Líquidas | B14: Net Interest, Monetary and Exchange Variations | C14: 11684 | D14: 15913 | E14: 53518 | F14: 57577 | G14: 61964 | H14: 69446 | I14: 79904 | J14: 73274 | K14: 79053 | L14: 74548 | M14: 68556 | N14: 78140 | O14: 76753 | P14: 59048 | Q14: 72388 | R14: 61847 | S14: 69317 | T14: 71111 | U14: 78254
A16: Variação em ativos e passivos operacionais: | B16: Changes in operating assets and liabilities:
A17: Contas a Receber de Clientes | B17: Trade Receivables | C17: -7268 | D17: -9288 | E17: -23729 | F17: 13956 | G17: -57022 | H17: -35728 | I17: -24103 | J17: 23408 | K17: -31283 | L17: -23362 | M17: -28629 | N17: 12709 | O17: -48249 | P17: -20963 | Q17: -9516 | R17: 7168 | S17: -97980 | T17: -39949 | U17: -18272
A18: Impostos a Recuperar | B18: Recoverable Taxes | C18: -765 | D18: -4634 | E18: 4959 | F18: -32888 | G18: -9605 | H18: -38503 | I18: -11639 | J18: -15689 | K18: 4883 | L18: -12064 | M18: 11219 | N18: -50265 | O18: -2696 | P18: -15995 | Q18: -16891 | R18: -15558 | S18: -23292 | T18: -25828 | U18: 1628
A19: Depósitos Judiciais | B19: Judicial Deposits | C19: -294 | D19: 1129 | E19: 1913 | F19: 10676 | G19: 724 | H19: -2784 | I19: 137 | J19: -1030 | K19: -2716 | L19: -1664 | M19: 226 | N19: -1308 | O19: 1384 | P19: -310 | Q19: -1076 | R19: 1655 | S19: -3637 | T19: -862 | U19: 170
A20: Outros Ativos | B20: Other Assets | C20: -21761 | D20: -21912 | E20: -18215 | F20: 20896 | G20: -5568 | H20: -38546 | I20: -11486 | J20: 28659 | K20: -34452 | L20: -54741 | M20: -694 | N20: 52219 | O20: -34053 | P20: -52836 | Q20: -23123 | R20: 26519 | S20: -24260 | T20: -108630 | U20: -43155
A21: Obrigações Sociais e Trabalhistas | B21: Labor Liabilities | C21: 5908 | D21: 42405 | E21: -31771 | F21: -15455 | G21: 3062 | H21: 92679 | I21: 7725 | J21: -29914 | K21: 3425 | L21: 100758 | M21: 27236 | N21: -34469 | O21: 7346 | P21: 102310 | Q21: 3762 | R21: -25972 | S21: 14907 | T21: 117314 | U21: 11116
A22: Fornecedores | B22: Trade and Other Payables | C22: -23023 | D22: -9128 | E22: 892 | F22: 2242 | G22: -3038 | H22: -1355 | I22: 15516 | J22: 10651 | K22: -16706 | L22: 22236 | M22: -6158 | N22: 20334 | O22: 13738 | P22: 23395 | Q22: -24223 | R22: 38155 | S22: 20763 | T22: -7930 | U22: -17763
A23: Comissões a Pagar | B23: Commissions Payable | C23: 8836 | D23: -3047 | E23: -1730 | F23: -680 | G23: 9359 | H23: -5186 | I23: 76 | J23: 3112 | K23: 8331 | L23: -5852 | M23: -3007 | N23: -2380 | O23: -3961 | P23: -8816 | Q23: 11218 | R23: 5496 | S23: -8291 | T23: 3541 | U23: 5287
A24: Impostos a Pagar | B24: Taxes and Contributions Payable | C24: -8460 | D24: -3130 | E24: 17141 | F24: 4814 | G24: 4840 | H24: -6151 | I24: 2289 | J24: -8447 | K24: -12907 | L24: -6356 | M24: -20989 | N24: 12981 | O24: -7832 | P24: 865 | Q24: 3274 | R24: 435 | S24: 9010 | T24: 16434 | U24: -14385
A25: Repasse para Parceiros | B25: Business Partners Payable | C25: 0 | D25: 0 | E25: 0 | F25: 0 | G25: 0 | H25: 0 | I25: 0 | J25: 0 | K25: 0 | L25: 0 | M25: 0 | N25: 0 | O25: 0 | P25: 0 | Q25: 0 | R25: 0 | S25: 0 | T25: 0 | U25: 0
A26: Outras Contas a Pagar | B26: Other Accounts Payable | C26: 5359 | D26: -25473 | E26: -31428 | F26: -8577 | G26: 5686 | H26: 1137 | I26: 6352 | J26: -24625 | K26: 12853 | L26: -9606 | M26: 8300 | N26: -30513 | O26: -7043 | P26: 266 | Q26: -8832 | R26: -7340 | S26: -900 | T26: -13208 | U26: 812
A27: Geração Operacional de Caixa | B27: Operating Cash Generation | C27: =SUM(C4,C7:C14,C17:C26) -> 157807 | D27: =SUM(D4,D7:D14,D17:D26) -> 167570 | E27: =SUM(E4,E7:E14,E17:E26) -> 163748 | F27: =SUM(F4,F7:F14,F17:F26) -> 281347 | G27: =SUM(G4,G7:G14,G17:G26) -> 257106 | H27: =SUM(H4,H7:H14,H17:H26) -> 290486 | I27: =SUM(I4,I7:I14,I17:I26) -> 333670 | J27: =SUM(J4,J7:J14,J17:J26) -> 325276 | ... U27: =SUM(U4,U7:U14,U17:U26) -> 456502
A29: Juros Pagos | B29: Interest paid | C29: -3638 | D29: -3123 | E29: -3192 | F29: -54073 | G29: -3038 | H29: -93502 | I29: -76737 | J29: -3113 | K29: -108686 | L29: -2246 | M29: -111614 | N29: -2375 | O29: -97810 | P29: -2434 | Q29: -76152 | R29: -1532 | S29: -80231 | T29: -2245 | U29: -112868
A30: IR e CSLL Pagos | B30: Tax Paid | C30: -45226 | D30: -23339 | E30: -29493 | F30: -33889 | G30: -50073 | H30: -9637 | I30: -32128 | J30: -22750 | K30: -51550 | L30: -28483 | M30: -63355 | N30: -46223 | O30: -53870 | P30: -41880 | Q30: -33442 | R30: -26960 | S30: -73808 | T30: -27197 | U30: -33572
A31: Caixa Líquido das Atividades Operacionais | B31: Net Cash from Operating Activities | C31: =SUM(C27,C29:C30) -> 108943 | D31: =SUM(D27,D29:D30) -> 141108 | E31: =SUM(E27,E29:E30) -> 131063 | F31: =SUM(F27,F29:F30) -> 193385 | G31: =SUM(G27,G29:G30) -> 203995 | H31: =SUM(H27,H29:H30) -> 187347 | I31: =SUM(I27,I29:I30) -> 224805 | J31: =SUM(J27,J29:J30) -> 299413 | ... U31: =SUM(U27,U29:U30) -> 310062
A33: Fluxo de caixa proveniente de atividades em investimentos | B33: Investing activities cash flow
A34: Dividendos Recebidos | B34: Dividends Received | C34: 0 | D34: 0 | E34: 1373 | F34: 746 | G34: 0 | H34: 0 | I34: - | J34: - | K34: 0 | L34: 0 | M34: 9073 | N34: 0 | O34: 0 | P34: 0 | Q34: 0 | R34: 0 | S34: 0 | T34: 0 | U34: 15598
A35: Aumento de Ativo Imobilizado | B35: Acquisitions of Prop. Plant and Equip. | C35: -9673 | D35: -13290 | E35: -34988 | F35: -35548 | G35: -14557 | H35: -18229 | I35: -35968 | J35: -32184 | K35: -37927 | L35: -22751 | M35: -37263 | N35: -25319 | O35: -23469 | P35: -37315 | Q35: -19760 | R35: -38704 | S35: -51840 | T35: -41874 | U35: -29901
A36: Aumento de Intangível | B36: Acquisition of Intangible Assets | C36: -10436 | D36: -13162 | E36: -39914 | F36: -17790 | G36: -9709 | H36: -23486 | I36: -21989 | J36: -25001 | K36: -28830 | L36: -21260 | M36: -83535 | N36: -20315 | O36: -36152 | P36: -41926 | Q36: -20138 | R36: -24238 | S36: -22318 | T36: -29688 | U36: -24285
A37: Mútuo com Franquias | B37: Franchises Loan | C37: -2996 | D37: -18166 | E37: -9876 | F37: -16626 | G37: 4471 | H37: 4747 | I37: 12101 | J37: 2938 | K37: 6195 | L37: 5518 | M37: -2484 | N37: 3921 | O37: 3585 | P37: 3821 | Q37: -18763 | R37: 10768 | S37: 2916 | T37: 3299 | U37: 2141
A38: Aquisição de Participação Societária | B38: Acquisition of Subsidiaries, Net of Cash | C38: 0 | D38: -1705030 | E38: -1 | F38: 0 | G38: -67589 | H38: -29947 | I38: -82218 | J38: -996 | K38: 0 | L38: -38748 | M38: -44451 | N38: -5668 | O38: -570907 | P38: -12666 | Q38: 0 | R38: -38871 | S38: 0 | T38: 0 | U38: -194227
A39: Pag. de Obrig. por Aquisição de Invest. | B39: Payments from Acquisitions of Subsidiaries | C39: -24065 | D39: -1389 | E39: -7788 | F39: -820 | G39: -119449 | H39: -50531 | I39: -13641 | J39: -25641 | K39: -11732 | L39: -25752 | M39: -5305 | N39: -707 | O39: -25641 | P39: -289349 | Q39: 0 | R39: -159681 | S39: -87484 | T39: -26683 | U39: -7521
A40: Venda (Aquisição) de Investimentos | B40: Proceeds from Sale of Subsid., Net of Cash | C40: 5041 | D40: 346 | E40: 41 | F40: 41 | G40: 6398 | H40: 40 | I40: 38 | J40: 43 | K40: 0 | L40: 54 | M40: 0 | N40: 0 | O40: 21144 | P40: 0 | Q40: 22030 | R40: -1365 | S40: 0 | T40: 0 | U40: 0
A41: Valor da Venda de Ativo Imobilizado | B41: Proceeds from Sale of Prop. Plant and Equip. | C41: 503 | D41: 882 | E41: 1752 | F41: 1099 | G41: 197 | H41: 1016 | I41: 444 | J41: 1412 | K41: 496 | L41: 718 | M41: 532 | N41: 1762 | O41: 7021 | P41: 1284 | Q41: 1531 | R41: 1676 | S41: 1442 | T41: 1107.3985 | U41: 2188
A42: Resgate (Investimento) Financeiros e Fundo CVC | B42: Financial and CVC Fund Rescue (Investment) | C42: 0 | D42: 0 | E42: 0 | F42: 0 | G42: -4192 | H42: -3491 | I42: -4083 | J42: -8315 | K42: 0 | L42: -4532 | M42: 385 | N42: -20689 | O42: -26010 | P42: 0 | Q42: -15399 | R42: -5616 | S42: -21389 | T42: -2438 | U42: -23173
A43: Caixa Recebido (Investido) - Techfin | B43: Net cash Received (Invested) - Techfin | C43: -193462 | D43: -5162 | E43: -7573 | F43: -9209 | G43: -7201 | H43: -5926 | I43: -18252 | J43: -2403 | K43: -5012 | L43: 235 | M43: 410000 | N43: 0 | O43: 0 | P43: 0 | Q43: 0 | R43: 0 | S43: 0 | T43: 0 | U43: 0
A44: Caixa Recebido (Investido) - RJ | B44: Net cash Received (Invested) - RJ | C44: 0 | D44: 0 | E44: 0 | F44: 0 | G44: 0 | H44: 0 | I44: 0 | J44: 0 | K44: 0 | L44: 0 | M44: 0 | N44: 0 | O44: 1300 | P44: 644 | Q44: 798 | R44: 437 | S44: -1619 | T44: -125 | U44: 154
...

Sheet Non-GAAP-Techfin-P&L
A1: PORTUGUÊS | B1: ENGLISH
A2: Demonstração de Resultados Trimestre (em R$ mil) | B2: Consolidated Income Statement Quarter (in R$ thousand) | C2: 1Q21 | D2: 2Q21 | E2: 3Q21 | F2: 4Q21 | G2: 1Q22 | H2: 2Q22 | I2: 3Q22 | J2: 4Q22 | K2: 1Q23 | L2: 2Q23 | M2: 3Q23 | N2: 4Q23 | O2: 1Q24 | P2: 2Q24 | Q2: 3Q24 | R2: 4Q24 | S2: 1Q25 | T2: 2Q25 | U2: 3Q25
A3: Receita de Techfin | B3: Techfin Net Revenue | C3: 55614 | D3: 60944 | E3: 73157 | F3: 91836 | G3: 82632 | H3: 93895 | I3: 117432 | J3: 117926 | K3: 99752 | L3: 88872 | M3: 136104 | N3: 118818 | O3: 99468 | P3: 102219 | Q3: 115023 | R3: 129834 | S3: 121025 | T3: 119141 | U3: 152513
A4: Custo de Funding | B4: Funding Cost | C4: -13356 | D4: -17285 | E4: -25150 | F4: -27291 | G4: -35517 | H4: -42020 | I4: -44753 | J4: -42462 | K4: -45283 | L4: -41386 | M4: -38270 | N4: -45751 | O4: -36474 | P4: -32377 | Q4: -36621 | R4: -33566 | S4: -41560 | T4: -46676 | U4: -50711
A5: Receita de Techfin Líquida de Funding | B5: Techfin Revenue - Net of funding | C5: =C3+C4 -> 42258 | D5: =D3+D4 -> 43659 | E5: =E3+E4 -> 48007 | F5: =F3+F4 -> 64545 | G5: =G3+G4 -> 47115 | H5: =H3+H4 -> 51875 | I5: =I3+I4 -> 72679 | J5: =J3+J4 -> 75464 | ... U5: =U3+U4 -> 101802
A6: Custos Operacionais | B6: Operational Costs | C6: -4869 | D6: -5385 | E6: -5949 | F6: -7336 | G6: -5895 | H6: -5680 | I6: -6944 | J6: -6772 | K6: -6444 | L6: -7572 | M6: -10444 | N6: -10547 | O6: -9208 | P6: -11324 | Q6: -10743 | R6: -13325 | S6: -8882 | T6: -7329 | U6: -7375
A7: Pesquisa e Desenvolvimento | B7: Research and Development | C7: -4499 | D7: -5823 | E7: -5865 | F7: -7972 | G7: -6722 | H7: -6180 | I7: -10038 | J7: -8384 | K7: -9384 | L7: -9032 | M7: -13202 | N7: -17710 | O7: -13526 | P7: -8251 | Q7: -8620 | R7: -9318 | S7: -7568 | T7: -8997 | U7: -9658
A8: Provisão para Perda Esperada | B8: Provision for Expected Credit Losses | C8: -1818 | D8: -4092 | E8: -4337 | F8: -5399 | G8: -10227 | H8: -7271 | I8: -7018 | J8: -16007 | K8: -8290 | L8: -6758 | M8: -9683 | N8: -8541 | O8: -7203 | P8: -8580 | Q8: -7562 | R8: -7262 | S8: -7103 | T8: -8511 | U8: -9930
A9: Demais Despesas Operacionais | B9: Other Operating Expenses | C9: -18033 | D9: -19946 | E9: -23276 | F9: -26084 | G9: -19421 | H9: -24104 | I9: -30231 | J9: -25799 | K9: -26409 | L9: -27202 | M9: -40299 | N9: -33981 | O9: -33598 | P9: -41359 | Q9: -42913 | R9: -42057.932 | S9: -43362 | T9: -45254 | U9: -49323
A10: Resultado da Equivalência Patrimônial | B10: Equity Pickup | C10: 0 | D10: 0 | E10: 0 | F10: 0 | G10: 0 | H10: 0 | I10: 0 | J10: 0 | K10: 0 | L10: 0 | M10: 0 | N10: 0 | O10: 0 | P10: 0 | Q10: 0 | R10: 0 | S10: 0 | T10: 0 | U10: 0
A11: EBITDA Ajustado Techfin | B11: Techfin Adjusted EBITDA | C11: =SUM(C5,C6,C7,C8,C9,C10) -> 13039 | D11: =SUM(D5,D6,D7,D8,D9,D10) -> 8413 | E11: =SUM(E5,E6,E7,E8,E9,E10) -> 8580 | F11: =SUM(F5,F6,F7,F8,F9,F10) -> 17754 | G11: =SUM(G5,G6,G7,G8,G9,G10) -> 4850 | H11: =SUM(H5,H6,H7,H8,H9,H10) -> 8640 | I11: =SUM(I5,I6,I7,I8,I9,I10) -> 18448 | J11: =SUM(J5,J6,J7,J8,J9,J10) -> 18502 | ... U11: =SUM(U5,U6,U7,U8,U9,U10) -> 25516
A12: % EBITDA Ajustado Techfin | B12: % Techfin Adjusted EBITDA | C12: =C11/C5 -> 0.30855696 | D12: =D11/D5 -> 0.19269795 | E12: =E11/E5 -> 0.17872394 | F12: =F11/F5 -> 0.27506391 | G12: =G11/G5 -> 0.10293962 | H12: =H11/H5 -> 0.16655422 | I12: =I11/I5 -> 0.25382848 | J12: =J11/J5 -> 0.24517651 | ... U12: =U11/U5 -> 0.25064341
A13: Depreciação e Amortização | B13: Depreciation and Amortization | C13: -15173 | D13: -15236 | E13: -15696 | F13: -15831 | G13: -14680 | H13: -11276 | I13: -10110 | J13: -10519 | K13: -10593 | L13: -10195 | M13: -10095 | N13: -10067 | O13: -9452 | P13: -9227 | Q13: -9222 | R13: -10197 | S13: -3190 | T13: -3193 | U13: -3191
A14: Resultado Financeiro | B14: Financial Result | C14: -286 | D14: -266 | E14: -570 | F14: -544 | G14: -94 | H14: -156 | I14: 423 | J14: 145 | K14: 134 | L14: 702 | M14: 3758 | N14: 4767 | O14: 4225 | P14: 3588 | Q14: 3408 | R14: 2437 | S14: 1870 | T14: 2952 | U14: 3076
A15: Imposto de Renda e Contrib. Social Ajustado | B15: Adjusted Income Tax and Social Contribution | C15: -822 | D15: 652 | E15: 254 | F15: -4950 | G15: -793 | H15: -861 | I15: 4631 | J15: -4240 | K15: 923 | L15: 4636 | M15: -6410 | N15: 603 | O15: -1008.64 | P15: -1810 | Q15: 1366 | R15: -6239.7431 | S15: -5282 | T15: -1826 | U15: -10598
A16: Amort. de Intang. de Aquisições Líq. de IR | B16: Net Effect of Amortization | C16: 9598.38 | D16: 9598.38 | E16: 9598.38 | F16: 9598.38 | G16: 8099.52 | H16: 6239.64 | I16: 5227.2 | J16: 5227.2 | K16: 5227.2 | L16: 5227.2 | M16: 5227.2 | N16: 5227.2 | O16: 5227.2 | P16: 5227.2 | Q16: 5227.2 | R16: 5227.2 | S16: 1247.4 | T16: 1247.4 | U16: 1247.4
A17: Lucro (Prejuízo) Ajustado da Techfin | B17: Adjusted Net Income (Loss) from Techfin | C17: =C11+C13+C14+C15+C16 -> 6356.38 | D17: =D11+D13+D14+D15+D16 -> 3161.38 | E17: =E11+E13+E14+E15+E16 -> 2166.38 | F17: =F11+F13+F14+F15+F16 -> 6027.38 | G17: =G11+G13+G14+G15+G16 -> -2617.48 | H17: =H11+H13+H14+H15+H16 -> 2586.64 | I17: =I11+I13+I14+I15+I16 -> 18619.2 | J17: =J11+J13+J14+J15+J16 -> 9115.2 | ... U17: =U11+U13+U14+U15+U16 -> 16050.4
A18: % Lucro (Prejuízo) da Techfin | B18: % Net Income (Loss) from Techfin | C18: =C17/C$5 -> 0.15041838 | D18: =D17/D$5 -> 0.072410729 | E18: =E17/E$5 -> 0.045126336 | F18: =F17/F$5 -> 0.093382601 | G18: =G17/G$5 -> -0.055555131 | H18: =H17/H$5 -> 0.04986294 | I18: =I17/I$5 -> 0.25618404 | J18: =J17/J$5 -> 0.12078872 | ... U18: =U17/U$5 -> 0.15766291
A19: Itens Extraordinários | B19: Extraordinary Items | C19: =SUM(C20:C22) -> 0 | D19: =SUM(D20:D22) -> 0 | E19: =SUM(E20:E22) -> 0 | F19: =SUM(F20:F22) -> 0 | G19: =SUM(G20:G22) -> 0 | H19: =SUM(H20:H22) -> 0 | I19: =SUM(I20:I22) -> 0 | J19: =SUM(J20:J22) -> 0 | ... U19: =SUM(U20:U22) -> 0
A20: Perda (Ganho) na Baixa de Ativos | B20: Lost (Earn) in Investment Sale | C20: 0 | D20: 0 | E20: 0 | F20: 0 | G20: 0 | H20: 0 | I20: 0 | J20: 0 | K20: 0 | L20: 0 | M20: 0 | N20: 0 | O20: 0 | P20: 0 | Q20: 0 | R20: -2518.068 | S20: 0 | T20: 0 | U20: 0
A21: Ajuste Extraord. Reestruturação Operacional | B21: Extraord. Adj. - Operatl. Restructuring | C21: 0 | D21: 0 | E21: 0 | F21: 0 | G21: 0 | H21: 0 | I21: 0 | J21: 0 | K21: 0 | L21: 0 | M21: 0 | N21: 0 | O21: -2646 | P21: 0 | Q21: 0 | R21: 0 | S21: 0 | T21: 0 | U21: 0
A22: Reoneração da Folha de Pagamento | B22: Adj. - Payroll Tax Surcharge | C22: 0 | D22: 0 | E22: 0 | F22: 0 | G22: 0 | H22: 0 | I22: 0 | J22: 0 | K22: 0 | L22: 0 | M22: 0 | N22: 0 | O22: 0 | P22: 0 | Q22: 0 | R22: -390 | S22: 0 | T22: 0 | U22: 0
A23: IR e CSLL (Itens Extraordinários) | B23: Taxes on Extraordinary Items | C23: =C19*-34% -> 0 | D23: =D19*-34% -> 0 | E23: =E19*-34% -> 0 | F23: =F19*-34% -> 0 | G23: =G19*-34% -> 0 | H23: =H19*-34% -> 0 | I23: =I19*-34% -> 0 | J23: =J19*-34% -> 0 | ... U23: =U19*-34% -> 0
A24: Amort. de Intang. de Aquisições Líq. de IR | B24: Net Effect of Amortization | C24: =-C16 -> -9598.38 | D24: =-D16 -> -9598.38 | E24: =-E16 -> -9598.38 | F24: =-F16 -> -9598.38 | G24: =-G16 -> -8099.52 | H24: =-H16 -> -6239.64 | I24: =-I16 -> -5227.2 | J24: =-J16 -> -5227.2 | ... U24: =-U16 -> -1247.4
A25: Lucro (Prejuízo) da Dimensão Techfin | B25: Net Income (Loss) from Techfin Dimension | C25: =C17+C19+C23+C24 -> -3242 | D25: =D17+D19+D23+D24 -> -6437 | E25: =E17+E19+E23+E24 -> -7432 | F25: =F17+F19+F23+F24 -> -3571 | G25: =G17+G19+G23+G24 -> -10717 | H25: =H17+H19+H23+H24 -> -3653 | I25: =I17+I19+I23+I24 -> 13392 | J25: =J17+J19+J23+J24 -> 3888 | ... U25: =U17+U19+U23+U24 -> 14803
A26: % Lucro (Prejuízo) da Dimensão Techfin | B26: % Net Income (Loss) from Techfin Dimension | C26: =C25/C$5 -> -0.076719201 | D26: =D25/D$5 -> -0.1474381 | E26: =E25/E$5 -> -0.15481076 | F26: =F25/F$5 -> -0.055325742 | G26: =G25/G$5 -> -0.22746471 | H26: =H25/H$5 -> -0.070419277 | I26: =I25/I$5 -> 0.1842623 | J26: =J25/J$5 -> 0.051521255 | ... U26: =U25/U$5 -> 0.14540972

Sheet Non-GAAP-Techfin-BS
A1: PORTUGUÊS | B1: ENGLISH
