Workbook

Sheet dados_original
A1: nome_arquivo | B1: nome_projeto | C1: data_comite | D1: tipo_comite | E1: cenario | F1: unidades | G1: avaliacao_unit | H1: fracao_terreno_pct | I1: valor_rs_m2 | J1: custo_construcao_rs | K1: custo_construcao_pct_vgv | L1: prazo_obra_meses | M1: custo_total_unit | N1: custo_adc_selling | O1: preco_nominal_unit | P1: preco_raso_unit | Q1: li_pct | R1: li_regua_pct | S1: margem_bruta_economica_pct | T1: margem_rasa_economica_pct | U1: exposicao_rs_mil | V1: exposicao_pct_vgv | W1: renda | X1: pct_ret1 | Y1: pct_tcd | Z1: raso_sobre_custo
A2: 2025.01.20 - Acqua Danubio -Lançamento.pdf | B2: Acqua Danúbio | C2: 20/01/2025 | D2: Book de Lançamento | E2: Aprovacao | F2: 388 | G2: 203835 | H2: 0.033 | I2: 398 | J2: 40555 | K2: 0.487 | L2: 18 | M2: 104524 | O2: 214464 | P2: 190902 | Q2: 0.203 | R2: 0.2 | S2: 0.401 | T2: 0.245 | U2: 16047 | V2: 0.12 | W2: 2521 | X2: 0.5 | Y2: =(O2-P2)/O2 -> 0.10986459 | Z2: =P2/M2 -> 1.8263939
A3: 2025.01.20 - Acqua Danubio -Lançamento.pdf | B3: Acqua Danúbio | C3: 20/01/2025 | D3: Book de Lançamento | E3: Real | F3: 597 | G3: 204302 | H3: 0.033 | I3: 398 | J3: 60520 | K3: 0.467 | L3: 18 | M3: 101373 | O3: 217040 | P3: 193235 | Q3: 0.201 | R3: 0.2 | S3: 0.42 | T3: 0.341 | U3: 16950 | V3: 0.127 | W3: 2555 | X3: 0.412 | Y3: =(O3-P3)/O3 -> 0.10968024 | Z3: =P3/M3 -> 1.9061782
A4: 2025.11.07 - Acqua Viena - Investimento - Respostas REV01.pdf | B4: Acqua Viena | C4: 07/11/2025 | D4: Book de Investimento | E4: Aprovacao | F4: 600 | G4: 234 | H4: 0.07 | I4: 848 | J4: 61094 | K4: 0.46 | L4: 17 | M4: 101823.4 | O4: 220700 | P4: 201227 | Q4: 0.2 | R4: 0.2 | S4: 0.4 | T4: 0.332 | U4: 13557 | V4: 0.09 | W4: 3373 | X4: 0.298 | Y4: =(O4-P4)/O4 -> 0.088232895 | Z4: =P4/M4 -> 1.9762353
A5: 2025.09.25 - Panorama Santo André - lançamento_Respostas.pdf | B5: Adriático (Panorama Santo André) | C5: 25/09/2025 | D5: Comitê de escritura e lançamento | E5: Aprovacao | F5: 642 | G5: 269717 | H5: 0.08 | I5: 1618 | J5: 72330 | K5: 0.415 | L5: 23 | M5: 112664 | O5: 271451 | P5: 248101 | Q5: 0.207 | R5: 0.2 | S5: 0.403 | T5: 0.339 | U5: 17174 | V5: 0.1 | W5: 4886 | X5: 0 | Y5: =(O5-P5)/O5 -> 0.086019208 | Z5: =P5/M5 -> 2.202132
A6: 2025.09.25 - Panorama Santo André - lançamento_Respostas.pdf | B6: Adriático (Panorama Santo André) | C6: 25/09/2025 | D6: Comitê de escritura e lançamento | E6: Real | F6: 642 | G6: 269717 | H6: 0.08 | I6: 1664 | J6: 72330 | K6: 0.409 | L6: 23 | M6: 112664 | O6: 275377 | P6: 252026 | Q6: 0.213 | R6: 0.2 | S6: 0.407 | T6: 0.343 | U6: 13648 | V6: 0.078 | W6: 4886 | X6: 0 | Y6: =(O6-P6)/O6 -> 0.084796479 | Z6: =P6/M6 -> 2.2369701
A7: 2025.02.14 - Altiplano Sunset - Investimento.pdf | B7: Altiplano Sunset | C7: 10/02/2025 | D7: Book de Investimento | E7: Aprovacao | F7: 712 | G7: 239775 | H7: 0.093 | I7: 1035 | J7: 69445 | K7: 0.435 | L7: 17 | M7: 97536 | O7: 224103 | P7: 201035 | Q7: 0.2 | R7: 0.2 | S7: 0.385 | T7: 0.306 | U7: 11267 | V7: 0.064 | W7: 3204 | X7: 0.381 | Y7: =(O7-P7)/O7 -> 0.10293481 | Z7: =P7/M7 -> 2.0611364
A8: 2025.08.04 - Alto da Colina - Escritura REV01_Resposta.pdf | B8: Alto da Colina | C8: 04/08/2025 | D8: Book de Escritura | E8: Aprovacao | F8: 696 | G8: 232598 | H8: 0.06 | I8: 792 | J8: 73392 | K8: 0.468 | L8: 22 | M8: 105448 | O8: 225486 | P8: 202688 | Q8: 0.2 | R8: 0.2 | S8: 0.382 | T8: 0.304 | U8: 18827 | V8: 0.119 | W8: 3205 | X8: 0.403 | Y8: =(O8-P8)/O8 -> 0.10110606 | Z8: =P8/M8 -> 1.9221607
A9: 2025.09.25 - Alto da Colina - Lançamento.pdf | B9: Alto da Colina | C9: 25/09/2025 | D9: Book de Lançamento | E9: Real | F9: 696 | G9: 232598 | H9: 0.06 | I9: 793 | J9: 72544 | K9: 0.463 | L9: 22 | M9: 104230 | O9: 224978 | P9: 202871 | Q9: 0.201 | R9: 0.2 | S9: 0.384 | T9: 0.308 | U9: 19280 | V9: 0.124 | W9: 3243 | X9: 0.333 | Y9: =(O9-P9)/O9 -> 0.098262941 | Z9: =P9/M9 -> 1.9463782
A10: 2025.09.05 -Alvorada Aricanduva - Escritura + Lanç_Respostas.pdf | B10: Alvorada Aricanduva (Sobral) | C10: 05/09/2025 | D10: Comitê de escritura e lançamento | E10: Aprovacao | F10: 577 | G10: 248000 | H10: 0.086 | I10: 3608 | J10: 60613 | K10: 0.446 | L10: 23 | M10: 105049 | O10: 235485 | P10: 220993 | Q10: 0.2 | R10: 0.2 | S10: 0.365 | T10: 0.318 | U10: 9982 | V10: 0.074 | W10: 3648 | X10: 0.25 | Y10: =(O10-P10)/O10 -> 0.061541075 | Z10: =P10/M10 -> 2.1037135
A11: 2025.09.05 -Alvorada Aricanduva - Escritura + Lanç_Respostas.pdf | B11: Alvorada Aricanduva (Sobral) | C11: 05/09/2025 | D11: Comitê de escritura e lançamento | E11: Real | F11: 577 | G11: 248000 | H11: 0.086 | I11: 3608 | J11: 60613 | K11: 0.448 | L11: 23 | M11: 105049 | O11: 234664 | P11: 217861 | Q11: 0.195 | R11: 0.2 | S11: 0.369 | T11: 0.314 | U11: 13375 | V11: 0.1 | W11: 3658 | X11: 0.25 | Y11: =(O11-P11)/O11 -> 0.071604507 | Z11: =P11/M11 -> 2.0738988
A12: 2025.06.17 - Americanópolis - Essencial.pdf | B12: Americanópolis | C12: 17/06/2025 | D12: Comitê Essencial | E12: Aprovacao | F12: 707 | G12: 277595 | H12: 0.127 | I12: 5273 | J12: 70183 | K12: 0.388 | L12: 22 | M12: 99269 | O12: 255663 | P12: 247267 | Q12: 0.2 | R12: 0.2 | S12: 0.377 | T12: 0.353 | U12: 22565 | V12: 0.114 | W12: 4495 | X12: 0.13 | Y12: =(O12-P12)/O12 -> 0.032840106 | Z12: =P12/M12 -> 2.4908783
A13: 2025.06.30 - Araçá Prime - Investimento - atualização.pdf | B13: Araçá Prime | C13: 30/06/2025 | D13: Book de Investimento | E13: Aprovacao | F13: 428 | G13: 290000 | H13: 0.105 | I13: 2846 | J13: 46758 | K13: 0.409 | L13: 18 | M13: 109247 | O13: 266782 | P13: 246703 | Q13: 0.185 | R13: 0.2 | S13: 0.396 | T13: 0.341 | U13: 22248 | V13: 0.187 | W13: 5211 | X13: 0 | Y13: =(O13-P13)/O13 -> 0.075263698 | Z13: =P13/M13 -> 2.258213
... A61: 2025.12.19 - Elevato Ramos - Lançamento REV03_Respostas.pdf | B61: Elevato Ramos – RZN2 | C61: 19/12/2025 | D61: Book de Lançamento - Respostas | E61: Aprovacao | F61: 494 | G61: 243006 | H61: 0.088 | I61: 2398 | J61: 49509 | K61: 0.42 | L61: 19 | M61: 100220 | O61: 238783 | P61: 217628 | Q61: 0.197 | R61: 0.2 | S61: 0.399 | T61: 0.334 | U61: 15273 | V61: 0.131 | W61: 4135 | X61: 0 | Y61: =(O61-P61)/O61 -> 0.088595084 | Z61: =P61/M61 -> 2.1715027
A62: 2026.03.20 - Elevato Ramos - Lançamento EE.1_Respostas.pdf | B62: Elevato Ramos – RZN2 | C62: 20/03/2026 | D62: Book de Lançamento | E62: Aprovacao | F62: 494 | G62: 243006 | H62: 0.087 | I62: 2451 | J62: 50111 | K62: 0.413 | L62: 19 | M62: 101439 | N62: 0.001 | O62: 245505 | P62: 216533 | Q62: 0.221 | R62: 0.22 | S62: 0.42 | T62: 0.33 | U62: 14440 | V62: 0.119 | W62: 4135 | X62: 0.182 | Y62: =(O62-P62)/O62 -> 0.11800982 | Z62: =P62/M62 -> 2.1346129
A63: 2026.03.20 - Elevato Ramos - Lançamento EE.1_Respostas.pdf | B63: Elevato Ramos – RZN2 | C63: 20/03/2026 | D63: Book de Lançamento | E63: Real | F63: 494 | G63: 243006 | H63: 0.087 | I63: 2472 | J63: 50111 | K63: 0.409 | L63: 19 | M63: 101439 | N63: 0.001 | O63: 248120 | P63: 219293 | Q63: 0.224 | R63: 0.22 | S63: 0.42 | T63: 0.331 | U63: 11933 | V63: 0.097 | W63: 4135 | X63: 0.182 | Y63: =(O63-P63)/O63 -> 0.11618169 | Z63: =P63/M63 -> 2.1618214
A64: 2026.03.20 - Elevato Ramos - Lançamento EE.1_Respostas.pdf | B64: Elevato Ramos – RZN2 | C64: 20/03/2026 | D64: Book de Lançamento | E64: Aprovacao | F64: 494 | G64: 243006 | H64: 0.087 | I64: 2472 | J64: 50111 | K64: 0.413 | L64: 19 | M64: 101439 | O64: 245505 | P64: 216533 | Q64: 0.221 | R64: 0.22 | S64: 0.42 | T64: 0.33 | U64: 14440 | V64: 0.119 | W64: 4135 | X64: 0.182 | Y64: =(O64-P64)/O64 -> 0.11800982 | Z64: =P64/M64 -> 2.1346129
A65: 2025.11.03 - Elevato Trinitá - Investimento 2F - REV00 Final.pdf | B65: Elevato Trinità | C65: 03/11/2025 | D65: Comite Ampliado de Investimento | E65: Aprovacao | F65: 634 | G65: 288139 | H65: 0.158 | I65: 5027 | J65: 63007 | K65: 0.367 | L65: 17 | M65: 99380 | O65: 270979 | P65: 250150 | Q65: 0.2 | R65: 0.2 | S65: 0.395 | T65: 0.339 | U65: 9106 | V65: 0.048 | W65: 5299 | X65: 0 | Y65: =(O65-P65)/O65 -> 0.076865735 | Z65: =P65/M65 -> 2.5171061
A66: 2025.10.20 - Elevato Uno - Rev. c. Reneg. REV05 final.pdf | B66: Elevato Uno | C66: 20/10/2025 | D66: Comite de Reversão com Reneg. | E66: Aprovacao | F66: 370 | G66: 286589 | H66: 0.128 | I66: 6266 | J66: 37334 | K66: 0.36 | L66: 18 | M66: 100902 | O66: 280420 | P66: 258705 | Q66: 0.211 | R66: 0.2 | S66: 0.404 | T66: 0.348 | U66: 13492 | V66: 0.128 | W66: 5436 | X66: 0 | Y66: =(O66-P66)/O66 -> 0.077437415 | Z66: =P66/M66 -> 2.5639234
A67: 2025.05.19 - Encanto Piatã F2 - Lançamento REV02_Respostas.pdf | B67: Encanto Piatã - F2 | C67: 19/05/2025 | D67: Book de Lançamento | E67: Aprovacao | F67: 1043 | G67: 263317 | H67: 0.067 | I67: 1139 | J67: 91594 | K67: 0.347 | L67: 21 | M67: 87818 | O67: 253150 | P67: 229232 | Q67: 0.304 | R67: 0.2 | S67: 0.515 | T67: 0.459 | U67: 18808 | V67: 0.07 | W67: 4693 | X67: 0 | Y67: =(O67-P67)/O67 -> 0.094481533 | Z67: =P67/M67 -> 2.6103077
A68: 2025.05.19 - Encanto Piatã F2 - Lançamento REV02_Respostas.pdf | B68: Encanto Piatã - F2 | C68: 19/05/2025 | D68: Book de Lançamento | E68: Real | F68: 1043 | G68: 263317 | H68: 0.066 | I68: 1139 | J68: 91594 | K68: 0.343 | L68: 21 | M68: 87818 | O68: 255972 | P68: 231996 | Q68: 0.305 | R68: 0.2 | S68: 0.517 | T68: 0.46 | U68: 16646 | V68: 0.061 | W68: 4194 | X68: 0 | Y68: =(O68-P68)/O68 -> 0.093666495 | Z68: =P68/M68 -> 2.6417819
A69: 2026.03.02 - Encanto Piatã F3 - Lançamento REV01.pdf | B69: Encanto Piatã – F3 | C69: 02/03/2026 | D69: Book de Lançamento | E69: Aprovacao | F69: 379 | G69: 266898 | H69: 0.063 | I69: 425 | J69: 36597 | K69: 0.346 | L69: 18 | M69: 96561 | O69: 279141 | P69: 245636 | Q69: 0.329 | R69: 0.306 | S69: 0.526 | T69: 0.451 | U69: 11316 | V69: 0.107 | W69: 4291 | X69: 0 | Y69: =(O69-P69)/O69 -> 0.12002895 | Z69: =P69/M69 -> 2.5438428
A70: 2026.03.02 - Encanto Piatã F3 - Lançamento REV01.pdf | B70: Encanto Piatã – F3 | C70: 02/03/2026 | D70: Book de Lançamento | E70: Real | F70: 379 | G70: 266898 | H70: 0.064 | I70: 425 | J70: 36597 | K70: 0.353 | L70: 18 | M70: 96561 | O70: 273488 | P70: 240662 | Q70: 0.337 | R70: 0.22 | S70: 0.521 | T70: 0.446 | U70: 8234 | V70: 0.079 | W70: 4291 | X70: 0 | Y70: =(O70-P70)/O70 -> 0.1200272 | Z70: =P70/M70 -> 2.4923313
A71: 2025.04.01 - Essence Butantã - Reversão - R01.pdf | B71: Essence Butantã (Eiras Garcia) | C71: 02/04/2025 | D71: Book de Reversão Sem Reneg | E71: Aprovacao | F71: 409 | G71: 297115 | H71: 0.084 | I71: 4380 | J71: 43662 | K71: 0.422 | L71: 22 | M71: 106753 | O71: 253073 | P71: 236834 | Q71: 0.2 | R71: 0.2 | S71: 0.399 | T71: 0.352 | U71: 13823 | V71: 0.124 | W71: 4224 | X71: 0 | Y71: =(O71-P71)/O71 -> 0.064167256 | Z71: =P71/M71 -> 2.2185231
A72: 28.11.2025 - Essence Caucaia - Investimento - Respostas.pdf | B72: Essence Caucaia I, II e III (Terreno 710) | C72: 28/11/2025 | D72: Book de Investimento | E72: Aprovacao | F72: 1500 | G72: 207147 | H72: 0.085 | I72: 420 | J72: 137990 | K72: 0.462 | L72: 14 | M72: 91993 | O72: 199237 | P72: 181500 | Q72: 0.213 | R72: 0.2 | S72: 0.385 | T72: 0.319 | U72: 17242 | V72: 0.052 | W72: 2733 | X72: 0.756 | Y72: =(O72-P72)/O72 -> 0.089024629 | Z72: =P72/M72 -> 1.9729762
A73: 25.06.2025 - Essence Maracanaú I - Investimento_respostas comitê_R02.pdf | B73: Essence Maracanaú I (Terreno 626) | C73: 30/06/2025 | D73: Book de Investimento | E73: Aprovacao | F73: 432 | G73: 221581 | H73: 0.09 | I73: 431 | J73: 43803 | K73: 0.469 | L73: 11 | M73: 101395 | O73: 216050 | P73: 194800 | Q73: 0.202 | R73: 0.2 | S73: 0.372 | T73: 0.306 | U73: 9597 | V73: 0.094 | W73: 2604 | X73: 0.541 | Y73: =(O73-P73)/O73 -> 0.098356862 | Z73: =P73/M73 -> 1.9211993
A74: 25.06.2025 - Essence Maracanaú II - Investimento_respostas comitê_R02.pdf | B74: Essence Maracanaú II (Terreno 626) | C74: 30/06/2025 | D74: Book de Investimento | E74: Aprovacao | F74: 432 | G74: 221581 | H74: 0.09 | I74: 431 | J74: 43803 | K74: 0.469 | L74: 11 | M74: 101395 | O74: 216050 | P74: 194800 | Q74: 0.202 | R74: 0.2 | S74: 0.372 | T74: 0.306 | U74: 9597 | V74: 0.094 | W74: 2604 | X74: 0.541 | Y74: =(O74-P74)/O74 -> 0.098356862 | Z74: =P74/M74 -> 1.9211993
A75: 2025.08.25 - Estação Bordignon - Escritura 3 - final.pdf | B75: Estação Bordignon | C75: 25/08/2025 | D75: Book de Escritura | E75: Aprovacao | F75: 360 | G75: 235261 | H75: 0.111 | I75: 893 | J75: 33069 | K75: 0.399 | L75: 12 | M75: 91857 | O75: 230353 | P75: 210193 | Q75: 0.232 | R75: 0.2 | S75: 0.417 | T75: 0.36 | U75: 13056 | V75: 0.157 | W75: 3540 | X75: 0.188 | Y75: =(O75-P75)/O75 -> 0.087517853 | Z75: =P75/M75 -> 2.2882633
... A168: 2025.04.25 - Ventura III - Lançamento_Respostas.pdf | B168: Parque Ventura III | C168: 25/04/2025 | D168: Book de Lançamento | E168: Real | F168: 946 | G168: 213717 | H168: 0.024 | I168: 384 | J168: 95023 | K168: 0.483 | L168: 19 | M168: 100447 | O168: 207813 | P168: 185421 | Q168: 0.21 | R168: 0.2 | S168: 0.422 | T168: 0.345 | U168: 19369 | V168: 0.092 | W168: 2742 | X168: 0.519 | Y168: =(O168-P168)/O168 -> 0.10775072 | Z168: =P168/M168 -> 1.8459586
A169: 2025.12.09 - Protendit - Essencial_v1 2.pdf | B169: Pedro de Castilho (PROTENDIT) | C169: 08/12/2025 | E169: Aprovacao | F169: 952 | G169: 230000 | H169: 0.099 | I169: 2086 | J169: 93190 | K169: 0.447 | L169: 25 | M169: 97888 | O169: 219216 | P169: 197616 | Q169: 0.201 | R169: 0.2 | S169: 0.36 | T169: 0.28 | U169: 15303 | V169: 0.067 | W169: 2573 | X169: 0.75 | Y169: =(O169-P169)/O169 -> 0.098532954 | Z169: =P169/M169 -> 2.018797
A170: 2025.12.01 - Pirajussara - Essencial de Investimento.pdf | B170: Pirajussara | C170: 02/12/2025 | E170: Aprovacao | F170: 1103 | G170: 299691 | H170: 0.17 | I170: 4474 | J170: 111238 | K170: 0.364 | L170: 22 | M170: 100851 | O170: 276768 | P170: 260917 | Q170: 0.2 | R170: 0.2 | S170: 0.378 | T170: 0.335 | U170: 13544 | V170: 0.038 | W170: 5311 | X170: 0.009 | Y170: =(O170-P170)/O170 -> 0.057271794 | Z170: =P170/M170 -> 2.5871533
A171: 2025.12.12 - Pituba Prime - Investimento REV03_Resposta.pdf | B171: Pituba Prime | C171: 12/12/2025 | D171: Book de Investimento | E171: Aprovacao | F171: 428 | G171: 297220 | H171: 0.105 | I171: 2902 | J171: 48140 | K171: 0.388 | L171: 20 | M171: 112476 | O171: 289733 | P171: 266959 | Q171: 0.224 | R171: 0.2 | S171: 0.419 | T171: 0.363 | U171: 10380 | V171: 0.081 | W171: 5876 | X171: 0 | Y171: =(O171-P171)/O171 -> 0.078603404 | Z171: =P171/M171 -> 2.3734752
A172: 26.05.2025 - Plenum Camaçari - Investimento REV02.pdf | B172: Plenum Camaçari | C172: 26/05/2025 | D172: Book de Investimento | E172: Aprovacao | F172: 714 | G172: 212269 | H172: 0.036 | I172: 413 | J172: 74873 | K172: 0.486 | L172: 17 | M172: 104864 | O172: 215611 | P172: 197671 | Q172: 0.201 | R172: 0.2 | S172: 0.392 | T172: 0.331 | U172: 19963 | V172: 0.12 | W172: 2889 | X172: 0.511 | Y172: =(O172-P172)/O172 -> 0.083205402 | Z172: =P172/M172 -> 1.8850225
A173: 2025.11.17 - Portal de Salvador - Reversão cReneg. 2.pdf | B173: Portal de Salvador | C173: 17/11/2025 | D173: Book de Reversão c/ Reneg. | E173: Aprovacao | F173: 1378 | G173: 239731 | H173: 0.086 | I173: 641 | J173: 134632 | K173: 0.402 | L173: 20 | M173: 97701 | O173: 242979 | P173: 223367 | Q173: 0.2 | R173: 0.2 | S173: 0.435 | T173: 0.38 | U173: 17996 | V173: 0.049 | W173: 3454 | X173: 0.144 | Y173: =(O173-P173)/O173 -> 0.080714794 | Z173: =P173/M173 -> 2.2862304
A174: 2026.02.20 - Porto Lima - Escritura rv2.1_Respostas.pdf | B174: Porto Lima & Porto Seleta | C174: 20/02/2026 | D174: Book de Escritura | E174: Aprovacao | F174: 907 | G174: 202491 | H174: 0.044 | I174: 371 | J174: 85372 | K174: 0.443 | L174: 12 | M174: 94126 | O174: 212375 | P174: 187804 | Q174: 0.253 | R174: 0.22 | S174: 0.433 | T174: 0.35 | U174: 19167 | V174: 0.096 | W174: 2581 | X174: 0.721 | Y174: =(O174-P174)/O174 -> 0.11569629 | Z174: =P174/M174 -> 1.9952404
A175: 16.03.26 - Porto Lima - Lançamento EE.1.pdf | B175: Porto Lima & Porto Seleta | C175: 16/03/2026 | D175: Book de Lançamento | E175: Aprovacao | F175: 907 | G175: 206720 | H175: 0.044 | I175: 371 | J175: 88708 | K175: 0.464 | L175: 12 | M175: 97804 | N175: -0.004 | O175: 210643 | P175: 185785 | Q175: 0.23 | R175: 0.22 | S175: 0.412 | T175: 0.324 | U175: 19649 | V175: 0.1 | W175: 2535 | X175: 0.721 | Y175: =(O175-P175)/O175 -> 0.11801009 | Z175: =P175/M175 -> 1.8995644
A176: 16.03.26 - Porto Lima - Lançamento EE.1.pdf | B176: Porto Lima & Porto Seleta | C176: 16/03/2026 | D176: Book de Lançamento | E176: Real | F176: 907 | G176: 206720 | H176: 0.045 | I176: 371 | J176: 88876 | K176: 0.476 | L176: 12 | M176: 97989 | N176: -0.004 | O176: 206061 | P176: 181743 | Q176: 0.205 | R176: 0.22 | S176: 0.39 | T176: 0.296 | U176: 16217 | V176: 0.084 | W176: 2535 | X176: 0.721 | Y176: =(O176-P176)/O176 -> 0.1180136 | Z176: =P176/M176 -> 1.8547286
A177: 2025.04.28 - Porto Lima - Reversao c Reneg final.pdf | B177: Porto Lima I – F1 | C177: 28/04/2025 | D177: Book de Reversão com Renegociação | E177: Aprovacao | F177: 276 | G177: 202743 | H177: 0.048 | I177: 374 | J177: 26472 | K177: 0.487 | L177: 11 | M177: 95913 | O177: 197025 | P177: 175906 | Q177: 0.191 | R177: 0.2 | S177: 0.358 | T177: 0.3 | U177: 11707 | V177: 0.204 | W177: 2550 | X177: 0.716 | Y177: =(O177-P177)/O177 -> 0.10718944 | Z177: =P177/M177 -> 1.8340162
A178: 2025.11.24 - Porto Valência F2 - Lançamento_Respostas (1) 1.pdf | B178: Porto Valência F2 | C178: 28/11/2025 - Respostas | D178: Book de Lançamento | E178: Aprovacao | F178: 140 | G178: 203600 | H178: 0.034 | I178: 100 | J178: 12632 | K178: 0.424 | L178: 8 | M178: 90225 | O178: 212877 | P178: 191657 | Q178: 0.213 | R178: 0.301 | S178: 0.46 | T178: 0.396 | U178: 5135 | V178: 0.182 | W178: 2907 | X178: 0.2 | Y178: =(O178-P178)/O178 -> 0.099681976 | Z178: =P178/M178 -> 2.1242117
A179: 2025.11.24 - Porto Valência F2 - Lançamento_Respostas (1) 1.pdf | B179: Porto Valência F2 | C179: 28/11/2025 - Respostas | D179: Book de Lançamento | E179: Real | F179: 140 | G179: 203600 | H179: 0.036 | I179: 100 | J179: 12632 | K179: 0.451 | L179: 8 | M179: 90225 | O179: 200183 | P179: 180863 | Q179: 0.184 | R179: 0.2 | S179: 0.396 | T179: 0.352 | U179: 5135 | V179: 0.182 | W179: 2907 | X179: 0.6 | Y179: =(O179-P179)/O179 -> 0.096511692 | Z179: =P179/M179 -> 2.0045774
...

Sheet dados_filtrado
A1: nome_arquivo | B1: nome_projeto | C1: data_comite | D1: tipo_comite | E1: cenario | F1: unidades | G1: avaliacao_unit | H1: fracao_terreno_pct | I1: valor_rs_m2 | J1: custo_construcao_rs | K1: custo_construcao_pct_vgv | L1: prazo_obra_meses | M1: custo_total_unit | N1: custo_adc_selling | O1: preco_nominal_unit | P1: preco_raso_unit | Q1: li_pct | R1: li_regua_pct | S1: margem_bruta_economica_pct | T1: margem_rasa_economica_pct | U1: exposicao_rs_mil | V1: exposicao_pct_vgv | W1: renda | X1: pct_ret1 | Y1: pct_tcd | Z1: raso_sobre_custo | AA1: MÊS | AB1: FAIXA | AC1: FLAG | AD1: TRI | AE1: Range LI | AF1: Range MR | AG1: Range MB
A2: 2025.01.13 - Jaguaribe Prime - Investimento 1.1.pdf | B2: Jaguaribe Prime | C2: 45670 | D2: Book de Investimento | E2: Aprovacao | F2: 1143 | G2: 292021 | H2: 0.138 | I2: 2293 | J2: 107842 | K2: 0.347 | L2: 19 | M2: 94350 | O2: 271870 | P2: 244467 | Q2: 0.206 | R2: 0.2 | S2: 0.428 | T2: 0.356 | U2: 24694 | V2: 0.072 | W2: 4682 | X2: 0 | Y2: =(O2-P2)/O2 -> 0.1007945 | Z2: =P2/M2 -> 2.5910652 | AA2: =DATE(YEAR(C2),MONTH(C2),1) -> 45658 | AB2: =IF(X2>=0.5,"Faixa 1",IF(X2=0,"Faixa 3","Faixa 2")) -> Faixa 3 | AC2: 1 | AD2: =YEAR(AA2)&"-"&IF(MONTH(AA2)<4,1,IF(MONTH(AA2)<7,2,IF(MONTH(AA2)<10,3,4)))&"T" -> 2025-1T | AE2: =IF((Q2-R2)<0.005,"Até +0,5%",IF((Q2-R2)<0.01,"Ate +1%","Acima de +1%")) -> Ate +1% | AF2: =IF($T2<=0.32,"Ate 32%",IF($T2<=0.34,"Ate 34%","Acima de 34%")) -> Acima de 34% | AG2: =IF($S2<=0.39,"Ate 39%",IF($S2<=0.41,"Ate 41%","Acima de 41%")) -> Acima de 41%
A3: 2025.01.20 - Acqua Danubio -Lançamento.pdf | B3: Acqua Danúbio | C3: 45677 | D3: Book de Lançamento | E3: Aprovacao | F3: 388 | G3: 203835 | H3: 0.033 | I3: 398 | J3: 40555 | K3: 0.487 | L3: 18 | M3: 104524 | O3: 214464 | P3: 190902 | Q3: 0.203 | R3: 0.2 | S3: 0.401 | T3: 0.245 | U3: 16047 | V3: 0.12 | W3: 2521 | X3: 0.5 | Y3: =(O3-P3)/O3 -> 0.10986459 | Z3: =P3/M3 -> 1.8263939 | AA3: =DATE(YEAR(C3),MONTH(C3),1) -> 45658 | AB3: =IF(X3>=0.5,"Faixa 1",IF(X3=0,"Faixa 3","Faixa 2")) -> Faixa 1 | AC3: 1 | AD3: =YEAR(AA3)&"-"&IF(MONTH(AA3)<4,1,IF(MONTH(AA3)<7,2,IF(MONTH(AA3)<10,3,4)))&"T" -> 2025-1T | AE3: =IF((Q3-R3)<0.005,"Até +0,5%",IF((Q3-R3)<0.01,"Ate +1%","Acima de +1%")) -> Até +0,5% | AF3: =IF($T3<=0.32,"Ate 32%",IF($T3<=0.34,"Ate 34%","Acima de 34%")) -> Ate 32% | AG3: =IF($S3<=0.39,"Ate 39%",IF($S3<=0.41,"Ate 41%","Acima de 41%")) -> Ate 41%
A4: 2025.01.27 - Reserva dos Colibris (Investimento).pdf | B4: Reserva dos Colibris | C4: 45684 | D4: Book de Investimento | E4: Aprovacao | F4: 464 | G4: 229763 | H4: 0.085 | I4: 937 | J4: 46844 | K4: 0.446 | L4: 19 | M4: 100957 | O4: 202427 | P4: 202427 | Q4: 0.203 | R4: 0.2 | S4: 0.379 | T4: 0.297 | U4: 10676 | V4: 0.096 | W4: 3175 | X4: 0.5 | Y4: =(O4-P4)/O4 -> 0 | Z4: =P4/M4 -> 2.0050814 | AA4: =DATE(YEAR(C4),MONTH(C4),1) -> 45658 | AB4: =IF(X4>=0.5,"Faixa 1",IF(X4=0,"Faixa 3","Faixa 2")) -> Faixa 1 | AC4: 1 | AD4: =YEAR(AA4)&"-"&IF(MONTH(AA4)<4,1,IF(MONTH(AA4)<7,2,IF(MONTH(AA4)<10,3,4)))&"T" -> 2025-1T | AE4: =IF((Q4-R4)<0.005,"Até +0,5%",IF((Q4-R4)<0.01,"Ate +1%","Acima de +1%")) -> Até +0,5% | AF4: =IF($T4<=0.32,"Ate 32%",IF($T4<=0.34,"Ate 34%","Acima de 34%")) -> Ate 32% | AG4: =IF($S4<=0.39,"Ate 39%",IF($S4<=0.41,"Ate 41%","Acima de 41%")) -> Ate 39%
A5: 2025.02.14 - Altiplano Sunset - Investimento.pdf | B5: Altiplano Sunset | C5: 45698 | D5: Book de Investimento | E5: Aprovacao | F5: 712 | G5: 239775 | H5: 0.093 | I5: 1035 | J5: 69445 | K5: 0.435 | L5: 17 | M5: 97536 | O5: 224103 | P5: 201035 | Q5: 0.2 | R5: 0.2 | S5: 0.385 | T5: 0.306 | U5: 11267 | V5: 0.064 | W5: 3204 | X5: 0.381 | Y5: =(O5-P5)/O5 -> 0.10293481 | Z5: =P5/M5 -> 2.0611364 | AA5: =DATE(YEAR(C5),MONTH(C5),1) -> 45689 | AB5: =IF(X5>=0.5,"Faixa 1",IF(X5=0,"Faixa 3","Faixa 2")) -> Faixa 2 | AC5: 1 | AD5: =YEAR(AA5)&"-"&IF(MONTH(AA5)<4,1,IF(MONTH(AA5)<7,2,IF(MONTH(AA5)<10,3,4)))&"T" -> 2025-1T | AE5: =IF((Q5-R5)<0.005,"Até +0,5%",IF((Q5-R5)<0.01,"Ate +1%","Acima de +1%")) -> Até +0,5% | AF5: =IF($T5<=0.32,"Ate 32%",IF($T5<=0.34,"Ate 34%","Acima de 34%")) -> Ate 32% | AG5: =IF($S5<=0.39,"Ate 39%",IF($S5<=0.41,"Ate 41%","Acima de 41%")) -> Ate 39%
A6: 2025.02.10- Melodia Jaçanã - Comitê Escritura +Lançamento - Respostas.pdf | B6: Melodia Jaçanã | C6: 45698 | D6: Book de Escritura e Lançamento | E6: Aprovacao | F6: 768 | G6: 253188 | H6: 0.102 | I6: 3263 | J6: 74484 | K6: 0.401 | L6: 24 | M6: 96984 | O6: 217773 | P6: 217773 | Q6: 0.2 | R6: 0.2 | S6: 0.376 | T6: 0.298 | U6: 14761 | V6: 0.079 | W6: 3893 | X6: 0.15 | Y6: =(O6-P6)/O6 -> 0 | Z6: =P6/M6 -> 2.2454529 | AA6: =DATE(YEAR(C6),MONTH(C6),1) -> 45689 | AB6: =IF(X6>=0.5,"Faixa 1",IF(X6=0,"Faixa 3","Faixa 2")) -> Faixa 2 | AC6: 1 | AD6: =YEAR(AA6)&"-"&IF(MONTH(AA6)<4,1,IF(MONTH(AA6)<7,2,IF(MONTH(AA6)<10,3,4)))&"T" -> 2025-1T | AE6: =IF((Q6-R6)<0.005,"Até +0,5%",IF((Q6-R6)<0.01,"Ate +1%","Acima de +1%")) -> Até +0,5% | AF6: =IF($T6<=0.32,"Ate 32%",IF($T6<=0.34,"Ate 34%","Acima de 34%")) -> Ate 32% | AG6: =IF($S6<=0.39,"Ate 39%",IF($S6<=0.41,"Ate 41%","Acima de 41%")) -> Ate 39%
A7: 17.02.2025 - Estância Dourados I - Lançamento 1.pdf | B7: Estância Dourados I | C7: 45705 | D7: Book de Lançamento | E7: Aprovacao | F7: 376 | G7: 197323 | H7: 0.0767 | I7: 405 | J7: 34007 | K7: 0.435 | L7: 12 | M7: 89992 | O7: 208033 | P7: 179700 | Q7: 0.226 | R7: 0.2 | S7: 0.383 | T7: 0.325 | U7: 9595 | V7: 0.122 | W7: 2347 | X7: 0.75 | Y7: =(O7-P7)/O7 -> 0.13619474 | Z7: =P7/M7 -> 1.9968442 | AA7: =DATE(YEAR(C7),MONTH(C7),1) -> 45689 | AB7: =IF(X7>=0.5,"Faixa 1",IF(X7=0,"Faixa 3","Faixa 2")) -> Faixa 1 | AC7: 1 | AD7: =YEAR(AA7)&"-"&IF(MONTH(AA7)<4,1,IF(MONTH(AA7)<7,2,IF(MONTH(AA7)<10,3,4)))&"T" -> 2025-1T | AE7: =IF((Q7-R7)<0.005,"Até +0,5%",IF((Q7-R7)<0.01,"Ate +1%","Acima de +1%")) -> Acima de +1% | AF7: =IF($T7<=0.32,"Ate 32%",IF($T7<=0.34,"Ate 34%","Acima de 34%")) -> Ate 34% | AG7: =IF($S7<=0.39,"Ate 39%",IF($S7<=0.41,"Ate 41%","Acima de 41%")) -> Ate 39%
A8: 2025.02.17 - Vila Laura Prime - Escritura e Lançamento 4.pdf | B8: Vila Laura Prime | C8: 45705 | D8: Book de Escritura e Lançamento | E8: Aprovacao | F8: 538 | G8: 264796 | H8: 0.11 | I8: 1941 | J8: 50446 | K8: 0.369 | L8: 20 | M8: 93766 | O8: 254371 | P8: 236077 | Q8: 0.213 | R8: 0.2 | S8: 0.413 | T8: 0.362 | U8: 12773 | V8: 0.095 | W8: 4290 | X8: 0 | Y8: =(O8-P8)/O8 -> 0.071918576 | Z8: =P8/M8 -> 2.517725 | AA8: =DATE(YEAR(C8),MONTH(C8),1) -> 45689 | AB8: =IF(X8>=0.5,"Faixa 1",IF(X8=0,"Faixa 3","Faixa 2")) -> Faixa 3 | AC8: 1 | AD8: =YEAR(AA8)&"-"&IF(MONTH(AA8)<4,1,IF(MONTH(AA8)<7,2,IF(MONTH(AA8)<10,3,4)))&"T" -> 2025-1T | AE8: =IF((Q8-R8)<0.005,"Até +0,5%",IF((Q8-R8)<0.01,"Ate +1%","Acima de +1%")) -> Acima de +1% | AF8: =IF($T8<=0.32,"Ate 32%",IF($T8<=0.34,"Ate 34%","Acima de 34%")) -> Acima de 34% | AG8: =IF($S8<=0.39,"Ate 39%",IF($S8<=0.41,"Ate 41%","Acima de 41%")) -> Acima de 41%
A9: 2025.02.28 - Farol do Mucuripe - Comitê Lançamento - EE resp. (1) - LM.pdf | B9: Farol do Mucuripe | C9: 45712 | D9: Book de Lançamento | E9: Aprovacao | F9: 286 | G9: 244714 | H9: 0.09 | I9: 1237 | J9: 27873 | K9: 0.415 | L9: 17 | M9: 97457 | O9: 235028 | P9: 213469 | Q9: 0.2 | R9: 0.2 | S9: 0.404 | T9: 0.337 | U9: 9498 | V9: 0.142 | W9: 3513 | X9: 0.201 | Y9: =(O9-P9)/O9 -> 0.091729496 | Z9: =P9/M9 -> 2.1903917 | AA9: =DATE(YEAR(C9),MONTH(C9),1) -> 45689 | AB9: =IF(X9>=0.5,"Faixa 1",IF(X9=0,"Faixa 3","Faixa 2")) -> Faixa 2 | AC9: 1 | AD9: =YEAR(AA9)&"-"&IF(MONTH(AA9)<4,1,IF(MONTH(AA9)<7,2,IF(MONTH(AA9)<10,3,4)))&"T" -> 2025-1T | AE9: =IF((Q9-R9)<0.005,"Até +0,5%",IF((Q9-R9)<0.01,"Ate +1%","Acima de +1%")) -> Até +0,5% | AF9: =IF($T9<=0.32,"Ate 32%",IF($T9<=0.34,"Ate 34%","Acima de 34%")) -> Ate 34% | AG9: =IF($S9<=0.39,"Ate 39%",IF($S9<=0.41,"Ate 41%","Acima de 41%")) -> Ate 41%
A10: 2025.02.17 - Book Sol do Mediterrâneo - Respostas 6.pdf | B10: Sol do Mediterrâneo - F2 | C10: 45712 | D10: Book de Lançamento | E10: Aprovacao | F10: 208 | G10: 184176 | H10: 0.068 | I10: 108 | J10: 18297 | K10: 0.444 | L10: 10 | M10: 87968 | O10: 204470 | P10: 182253 | Q10: 0.275 | R10: 0.2 | S10: 0.425 | T10: 0.351 | U10: 3351 | V10: 0.078 | W10: 2019 | X10: 0.75 | Y10: =(O10-P10)/O10 -> 0.10865653 | Z10: =P10/M10 -> 2.0718102 | AA10: =DATE(YEAR(C10),MONTH(C10),1) -> 45689 | AB10: =IF(X10>=0.5,"Faixa 1",IF(X10=0,"Faixa 3","Faixa 2")) -> Faixa 1 | AC10: 1 | AD10: =YEAR(AA10)&"-"&IF(MONTH(AA10)<4,1,IF(MONTH(AA10)<7,2,IF(MONTH(AA10)<10,3,4)))&"T" -> 2025-1T | AE10: =IF((Q10-R10)<0.005,"Até +0,5%",IF((Q10-R10)<0.01,"Ate +1%","Acima de +1%")) -> Acima de +1% | AF10: =IF($T10<=0.32,"Ate 32%",IF($T10<=0.34,"Ate 34%","Acima de 34%")) -> Acima de 34% | AG10: =IF($S10<=0.39,"Ate 39%",IF($S10<=0.41,"Ate 41%","Acima de 41%")) -> Acima de 41%
A11: 2025.02.28 - Vale dos Lírios F2 - Lançamento - Resp 1.pdf | B11: Vale dos Lírios - F2 | C11: 45712 | D11: Book de Lançamento | E11: Aprovacao | F11: 316 | G11: 224993 | H11: 0.08 | I11: 467 | J11: 29690 | K11: 0.394 | L11: 16 | M11: 93957 | O11: 238501 | P11: 211939 | Q11: 0.237 | R11: 0.2 | S11: 0.44 | T11: 0.362 | U11: 9159 | V11: 0.122 | W11: 3357 | X11: 0.18 | Y11: =(O11-P11)/O11 -> 0.1113706 | Z11: =P11/M11 -> 2.2557021 | AA11: =DATE(YEAR(C11),MONTH(C11),1) -> 45689 | AB11: =IF(X11>=0.5,"Faixa 1",IF(X11=0,"Faixa 3","Faixa 2")) -> Faixa 2 | AC11: 1 | AD11: =YEAR(AA11)&"-"&IF(MONTH(AA11)<4,1,IF(MONTH(AA11)<7,2,IF(MONTH(AA11)<10,3,4)))&"T" -> 2025-1T | AE11: =IF((Q11-R11)<0.005,"Até +0,5%",IF((Q11-R11)<0.01,"Ate +1%","Acima de +1%")) -> Acima de +1% | AF11: =IF($T11<=0.32,"Ate 32%",IF($T11<=0.34,"Ate 34%","Acima de 34%")) -> Acima de 34% | AG11: =IF($S11<=0.39,"Ate 39%",IF($S11<=0.41,"Ate 41%","Acima de 41%")) -> Acima de 41%
A12: 2025.02.28 - Pq Ventura III - Escritura_Respostas_Final.pdf | B12: Parque Ventura III | C12: 45716 | D12: Book de Escritura | E12: Aprovacao | F12: 946 | G12: 213717 | H12: 0.023 | I12: 377 | J12: 92461 | K12: 0.46 | L12: 19 | M12: 97739 | O12: 212253 | P12: 187303 | Q12: 0.23 | R12: 0.2 | S12: 0.439 | T12: 0.356 | U12: 15373 | V12: 0.071 | W12: 2847 | X12: 0.48 | Y12: =(O12-P12)/O12 -> 0.1175484 | Z12: =P12/M12 -> 1.9163589 | AA12: =DATE(YEAR(C12),MONTH(C12),1) -> 45689 | AB12: =IF(X12>=0.5,"Faixa 1",IF(X12=0,"Faixa 3","Faixa 2")) -> Faixa 2 | AC12: 1 | AD12: =YEAR(AA12)&"-"&IF(MONTH(AA12)<4,1,IF(MONTH(AA12)<7,2,IF(MONTH(AA12)<10,3,4)))&"T" -> 2025-1T | AE12: =IF((Q12-R12)<0.005,"Até +0,5%",IF((Q12-R12)<0.01,"Ate +1%","Acima de +1%")) -> Acima de +1% | AF12: =IF($T12<=0.32,"Ate 32%",IF($T12<=0.34,"Ate 34%","Acima de 34%")) -> Acima de 34% | AG12: =IF($S12<=0.39,"Ate 39%",IF($S12<=0.41,"Ate 41%","Acima de 41%")) -> Acima de 41%
A13: 2025.03.17 - Frutas - Investimento.pdf | B13: FRUTAS | C13: 45733 | D13: Book de Investimento | E13: Aprovacao | F13: 320 | G13: 193641 | H13: 0.069 | I13: 532 | J13: 26722 | K13: 0.411 | L13: 13 | M13: 83505 | O13: 203268 | P13: 175186 | Q13: 0.253 | R13: 0.2 | S13: 0.453 | T13: 0.357 | U13: 8862 | V13: 0.124 | W13: 2171 | X13: 0.75 | Y13: =(O13-P13)/O13 -> 0.13815259 | Z13: =P13/M13 -> 2.0979103 | AA13: =DATE(YEAR(C13),MONTH(C13),1) -> 45717 | AB13: =IF(X13>=0.5,"Faixa 1",IF(X13=0,"Faixa 3","Faixa 2")) -> Faixa 1 | AC13: 1 | AD13: =YEAR(AA13)&"-"&IF(MONTH(AA13)<4,1,IF(MONTH(AA13)<7,2,IF(MONTH(AA13)<10,3,4)))&"T" -> 2025-1T | AE13: =IF((Q13-R13)<0.005,"Até +0,5%",IF((Q13-R13)<0.01,"Ate +1%","Acima de +1%")) -> Acima de +1% | AF13: =IF($T13<=0.32,"Ate 32%",IF($T13<=0.34,"Ate 34%","Acima de 34%")) -> Acima de 34% | AG13: =IF($S13<=0.39,"Ate 39%",IF($S13<=0.41,"Ate 41%","Acima de 41%")) -> Acima de 41%
... A115: 2025.11.14 - Santorini Prime - Investimento - Respostas.pdf | B115: Santorini Prime | C115: 45975 | D115: Book de Investimento | E115: Aprovacao | F115: 925 | G115: 348351 | H115: 0.077 | I115: 1846 | J115: 105691 | K115: 0.323 | L115: 19 | M115: 114261 | O115: 353573 | P115: 333894 | Q115: 0.234 | R115: 0.2 | S115: 0.464 | T115: 0.428 | U115: 45316 | V115: 0.133 | W115: 7999 | X115: 0 | Y115: =(O115-P115)/O115 -> 0.05565753 | Z115: =P115/M115 -> 2.9222044 | AA115: =DATE(YEAR(C115),MONTH(C115),1) -> 45962 | AB115: =IF(X115>=0.5,"Faixa 1",IF(X115=0,"Faixa 3","Faixa 2")) -> Faixa 3 | AC115: 1 | AD115: =YEAR(AA115)&"-"&IF(MONTH(AA115)<4,1,IF(MONTH(AA115)<7,2,IF(MONTH(AA115)<10,3,4)))&"T" -> 2025-4T | AE115: =IF((Q115-R115)<0.005,"Até +0,5%",IF((Q115-R115)<0.01,"Ate +1%","Acima de +1%")) -> Acima de +1% | AF115: =IF($T115<=0.32,"Ate 32%",IF($T115<=0.34,"Ate 34%","Acima de 34%")) -> Acima de 34% | AG115: =IF($S115<=0.39,"Ate 39%",IF($S115<=0.41,"Ate 41%","Acima de 41%")) -> Acima de 41%
A116: 2025.11.14 - São Martinho - Investimento - Respostas.pdf | B116: São Martinho | C116: 45975 | E116: Real | F116: 350 | G116: 295961 | H116: 0.102 | I116: 1466 | J116: 42433 | K116: 0.42 | L116: 19 | M116: 121236 | O116: 288964 | P116: 268477 | Q116: 0.209 | R116: 0.2 | S116: 0.382 | T116: 0.334 | U116: 10947 | V116: 0.101 | W116: 5271 | X116: 0 | Y116: =(O116-P116)/O116 -> 0.070898105 | Z116: =P116/M116 -> 2.214499 | AA116: =DATE(YEAR(C116),MONTH(C116),1) -> 45962 | AB116: =IF(X116>=0.5,"Faixa 1",IF(X116=0,"Faixa 3","Faixa 2")) -> Faixa 3 | AC116: 1 | AD116: =YEAR(AA116)&"-"&IF(MONTH(AA116)<4,1,IF(MONTH(AA116)<7,2,IF(MONTH(AA116)<10,3,4)))&"T" -> 2025-4T | AE116: =IF((Q116-R116)<0.005,"Até +0,5%",IF((Q116-R116)<0.01,"Ate +1%","Acima de +1%")) -> Ate +1% | AF116: =IF($T116<=0.32,"Ate 32%",IF($T116<=0.34,"Ate 34%","Acima de 34%")) -> Ate 34% | AG116: =IF($S116<=0.39,"Ate 39%",IF($S116<=0.41,"Ate 41%","Acima de 41%")) -> Ate 39%
A117: 17.11.2025 - Idealle Prime - Investimento REV02.pdf | B117: Idealle Prime (Terreno 289) | C117: 45978 | D117: Book de Investimento | E117: Aprovacao | F117: 753 | G117: 281992 | H117: 0.14 | I117: 2509 | J117: 74018 | K117: 0.371 | L117: 18 | M117: 98297 | O117: 264652 | P117: 239556 | Q117: 0.205 | R117: 0.2 | S117: 0.394 | T117: 0.324 | U117: 14685 | V117: 0.068 | W117: 4346 | X117: 0 | Y117: =(O117-P117)/O117 -> 0.094826414 | Z117: =P117/M117 -> 2.4370632 | AA117: =DATE(YEAR(C117),MONTH(C117),1) -> 45962 | AB117: =IF(X117>=0.5,"Faixa 1",IF(X117=0,"Faixa 3","Faixa 2")) -> Faixa 3 | AC117: 1 | AD117: =YEAR(AA117)&"-"&IF(MONTH(AA117)<4,1,IF(MONTH(AA117)<7,2,IF(MONTH(AA117)<10,3,4)))&"T" -> 2025-4T | AE117: =IF((Q117-R117)<0.005,"Até +0,5%",IF((Q117-R117)<0.01,"Ate +1%","Acima de +1%")) -> Até +0,5% | AF117: =IF($T117<=0.32,"Ate 32%",IF($T117<=0.34,"Ate 34%","Acima de 34%")) -> Ate 34% | AG117: =IF($S117<=0.39,"Ate 39%",IF($S117<=0.41,"Ate 41%","Acima de 41%")) -> Ate 41%
A118: 2025.11.17 - Leonel Martiniano - Essencial_v1.pdf | B118: Leonel Martiniano | C118: 45978 | D118: Book Essencial de Investimento | E118: Aprovacao | F118: 1794 | G118: 225000 | H118: 0.079 | I118: 3192 | J118: 183183 | K118: 0.461 | L118: 25 | M118: 102109 | O118: 221585 | P118: 199510 | Q118: 0.206 | R118: 0.2 | S118: 0.371 | T118: 0.291 | U118: 20086 | V118: 0.044 | W118: 2591 | X118: 0.75 | Y118: =(O118-P118)/O118 -> 0.099623169 | Z118: =P118/M118 -> 1.9538924 | AA118: =DATE(YEAR(C118),MONTH(C118),1) -> 45962 | AB118: =IF(X118>=0.5,"Faixa 1",IF(X118=0,"Faixa 3","Faixa 2")) -> Faixa 1 | AC118: 1 | AD118: =YEAR(AA118)&"-"&IF(MONTH(AA118)<4,1,IF(MONTH(AA118)<7,2,IF(MONTH(AA118)<10,3,4)))&"T" -> 2025-4T | AE118: =IF((Q118-R118)<0.005,"Até +0,5%",IF((Q118-R118)<0.01,"Ate +1%","Acima de +1%")) -> Ate +1% | AF118: =IF($T118<=0.32,"Ate 32%",IF($T118<=0.34,"Ate 34%","Acima de 34%")) -> Ate 32% | AG118: =IF($S118<=0.39,"Ate 39%",IF($S118<=0.41,"Ate 41%","Acima de 41%")) -> Ate 39%
A119: 2025.11.17 - Portal de Salvador - Reversão cReneg. 2.pdf | B119: Portal de Salvador | C119: 45978 | D119: Book de Reversão c/ Reneg. | E119: Aprovacao | F119: 1378 | G119: 239731 | H119: 0.086 | I119: 641 | J119: 134632 | K119: 0.402 | L119: 20 | M119: 97701 | O119: 242979 | P119: 223367 | Q119: 0.2 | R119: 0.2 | S119: 0.435 | T119: 0.38 | U119: 17996 | V119: 0.049 | W119: 3454 | X119: 0.144 | Y119: =(O119-P119)/O119 -> 0.080714794 | Z119: =P119/M119 -> 2.2862304 | AA119: =DATE(YEAR(C119),MONTH(C119),1) -> 45962 | AB119: =IF(X119>=0.5,"Faixa 1",IF(X119=0,"Faixa 3","Faixa 2")) -> Faixa 2 | AC119: 1 | AD119: =YEAR(AA119)&"-"&IF(MONTH(AA119)<4,1,IF(MONTH(AA119)<7,2,IF(MONTH(AA119)<10,3,4)))&"T" -> 2025-4T | AE119: =IF((Q119-R119)<0.005,"Até +0,5%",IF((Q119-R119)<0.01,"Ate +1%","Acima de +1%")) -> Até +0,5% | AF119: =IF($T119<=0.32,"Ate 32%",IF($T119<=0.34,"Ate 34%","Acima de 34%")) -> Acima de 34% | AG119: =IF($S119<=0.39,"Ate 39%",IF($S119<=0.41,"Ate 41%","Acima de 41%")) -> Acima de 41%
A120: 2025.11.17 - Solar dos Ventos Prime - Escritura e Lançamento EE REV03.pdf | B120: Solar dos Ventos Prime | C120: 45978 | D120: Book de Escritura e Lançamento | E120: Aprovacao | F120: 465 | G120: 284435 | H120: 0.108 | I120: 1797 | J120: 46074 | K120: 0.396 | L120: 19 | M120: 99083 | O120: 249897 | P120: 223879 | Q120: 0.214 | R120: 0.2 | S120: 0.401 | T120: 0.323 | U120: 10921 | V120: 0.095 | W120: 3727 | X120: 0.229 | Y120: =(O120-P120)/O120 -> 0.1041149 | Z120: =P120/M120 -> 2.2595097 | AA120: =DATE(YEAR(C120),MONTH(C120),1) -> 45962 | AB120: =IF(X120>=0.5,"Faixa 1",IF(X120=0,"Faixa 3","Faixa 2")) -> Faixa 2 | AC120: 1 | AD120: =YEAR(AA120)&"-"&IF(MONTH(AA120)<4,1,IF(MONTH(AA120)<7,2,IF(MONTH(AA120)<10,3,4)))&"T" -> 2025-4T | AE120: =IF((Q120-R120)<0.005,"Até +0,5%",IF((Q120-R120)<0.01,"Ate +1%","Acima de +1%")) -> Acima de +1% | AF120: =IF($T120<=0.32,"Ate 32%",IF($T120<=0.34,"Ate 34%","Acima de 34%")) -> Ate 34% | AG120: =IF($S120<=0.39,"Ate 39%",IF($S120<=0.41,"Ate 41%","Acima de 41%")) -> Ate 41%
A121: 2025.11.17 - Forte São Marcelo - Lançamento - Aprovação V3.pdf | B121: Viver Salvador – Forte São Marcelo | C121: 45978 | D121: Book de Lançamento | E121: Aprovacao | F121: 476 | G121: 204705 | H121: 0.036 | I121: 622 | J121: 47382 | K121: 0.478 | L121: 15 | M121: 99541 | O121: 208185 | P121: 187323 | Q121: 0.221 | R121: 0.2 | S121: 0.405 | T121: 0.333 | U121: 12892 | V121: 0.13 | W121: 2546 | X121: 0.666 | Y121: =(O121-P121)/O121 -> 0.10020895 | Z121: =P121/M121 -> 1.8818678 | AA121: =DATE(YEAR(C121),MONTH(C121),1) -> 45962 | AB121: =IF(X121>=0.5,"Faixa 1",IF(X121=0,"Faixa 3","Faixa 2")) -> Faixa 1 | AC121: 1 | AD121: =YEAR(AA121)&"-"&IF(MONTH(AA121)<4,1,IF(MONTH(AA121)<7,2,IF(MONTH(AA121)<10,3,4)))&"T" -> 2025-4T | AE121: =IF((Q121-R121)<0.005,"Até +0,5%",IF((Q121-R121)<0.01,"Ate +1%","Acima de +1%")) -> Acima de +1% | AF121: =IF($T121<=0.32,"Ate 32%",IF($T121<=0.34,"Ate 34%","Acima de 34%")) -> Ate 34% | AG121: =IF($S121<=0.39,"Ate 39%",IF($S121<=0.41,"Ate 41%","Acima de 41%")) -> Ate 41%
A122: 24.11.2025 - São Joaquim - Investimento.pdf | B122: São Joaquim | C122: 45985 | D122: Book de Investimento | E122: Aprovacao | F122: 333 | G122: 210465 | H122: 0.043 | I122: 304 | J122: 29496 | K122: 0.425 | L122: 14 | M122: 88577 | O122: 208220 | P122: 190122 | Q122: 0.253 | R122: 0.2 | S122: 0.457 | T122: 0.4 | U122: 11647 | V122: 0.158 | W122: 2803 | X122: 0.551 | Y122: =(O122-P122)/O122 -> 0.086917683 | Z122: =P122/M122 -> 2.1464037 | AA122: =DATE(YEAR(C122),MONTH(C122),1) -> 45962 | AB122: =IF(X122>=0.5,"Faixa 1",IF(X122=0,"Faixa 3","Faixa 2")) -> Faixa 1 | AC122: 1 | AD122: =YEAR(AA122)&"-"&IF(MONTH(AA122)<4,1,IF(MONTH(AA122)<7,2,IF(MONTH(AA122)<10,3,4)))&"T" -> 2025-4T | AE122: =IF((Q122-R122)<0.005,"Até +0,5%",IF((Q122-R122)<0.01,"Ate +1%","Acima de +1%")) -> Acima de +1% | AF122: =IF($T122<=0.32,"Ate 32%",IF($T122<=0.34,"Ate 34%","Acima de 34%")) -> Acima de 34% | AG122: =IF($S122<=0.39,"Ate 39%",IF($S122<=0.41,"Ate 41%","Acima de 41%")) -> Acima de 41%
A123: 28.11.2025 - Atilio 1407 - Escritura + Lançamento - Respostas.pdf | B123: Atílio 1407 | C123: 45989 | D123: Book de Escritura + Lançamento | E123: Aprovacao | F123: 874 | G123: 229573 | H123: 0.061 | I123: 999 | J123: 93824 | K123: 0.473 | L123: 20 | M123: 107350 | O123: 226816 | P123: 207123 | Q123: 0.179 | R123: 0.2 | S123: 0.38 | T123: 0.315 | U123: 13634 | V123: 0.067 | W123: 3189 | X123: 0.287 | Y123: =(O123-P123)/O123 -> 0.086823681 | Z123: =P123/M123 -> 1.9294178 | AA123: =DATE(YEAR(C123),MONTH(C123),1) -> 45962 | AB123: =IF(X123>=0.5,"Faixa 1",IF(X123=0,"Faixa 3","Faixa 2")) -> Faixa 2 | AC123: 1 | AD123: =YEAR(AA123)&"-"&IF(MONTH(AA123)<4,1,IF(MONTH(AA123)<7,2,IF(MONTH(AA123)<10,3,4)))&"T" -> 2025-4T | AE123: =IF((Q123-R123)<0.005,"Até +0,5%",IF((Q123-R123)<0.01,"Ate +1%","Acima de +1%")) -> Até +0,5% | AF123: =IF($T123<=0.32,"Ate 32%",IF($T123<=0.34,"Ate 34%","Acima de 34%")) -> Ate 32% | AG123: =IF($S123<=0.39,"Ate 39%",IF($S123<=0.41,"Ate 41%","Acima de 41%")) -> Ate 39%
A124: 2025.11.28 - Elevato Ramos - Escritura - Respostas_REV1.pdf | B124: Elevato Ramos – RZN2 | C124: 45989 | D124: Book de Escritura | E124: Aprovacao | F124: 494 | G124: 243279 | H124: 0.086 | I124: 2078 | J124: 50671 | K124: 0.43 | L124: 19 | M124: 102573 | O124: 238783 | P124: 217628 | Q124: 0.186 | R124: 0.2 | S124: 0.388 | T124: 0.322 | U124: 15664 | V124: 0.133 | W124: 4135 | X124: 0 | Y124: =(O124-P124)/O124 -> 0.088595084 | Z124: =P124/M124 -> 2.1216889 | AA124: =DATE(YEAR(C124),MONTH(C124),1) -> 45962 | AB124: =IF(X124>=0.5,"Faixa 1",IF(X124=0,"Faixa 3","Faixa 2")) -> Faixa 3 | AC124: 1 | AD124: =YEAR(AA124)&"-"&IF(MONTH(AA124)<4,1,IF(MONTH(AA124)<7,2,IF(MONTH(AA124)<10,3,4)))&"T" -> 2025-4T | AE124: =IF((Q124-R124)<0.005,"Até +0,5%",IF((Q124-R124)<0.01,"Ate +1%","Acima de +1%")) -> Até +0,5% | AF124: =IF($T124<=0.32,"Ate 32%",IF($T124<=0.34,"Ate 34%","Acima de 34%")) -> Ate 34% | AG124: =IF($S124<=0.39,"Ate 39%",IF($S124<=0.41,"Ate 41%","Acima de 41%")) -> Ate 39%
A125: 28.11.2025 - Essence Caucaia - Investimento - Respostas.pdf | B125: Essence Caucaia I, II e III (Terreno 710) | C125: 45989 | D125: Book de Investimento | E125: Aprovacao | F125: 1500 | G125: 207147 | H125: 0.085 | I125: 420 | J125: 137990 | K125: 0.462 | L125: 14 | M125: 91993 | O125: 199237 | P125: 181500 | Q125: 0.213 | R125: 0.2 | S125: 0.385 | T125: 0.319 | U125: 17242 | V125: 0.052 | W125: 2733 | X125: 0.756 | Y125: =(O125-P125)/O125 -> 0.089024629 | Z125: =P125/M125 -> 1.9729762 | AA125: =DATE(YEAR(C125),MONTH(C125),1) -> 45962 | AB125: =IF(X125>=0.5,"Faixa 1",IF(X125=0,"Faixa 3","Faixa 2")) -> Faixa 1 | AC125: 1 | AD125: =YEAR(AA125)&"-"&IF(MONTH(AA125)<4,1,IF(MONTH(AA125)<7,2,IF(MONTH(AA125)<10,3,4)))&"T" -> 2025-4T | AE125: =IF((Q125-R125)<0.005,"Até +0,5%",IF((Q125-R125)<0.01,"Ate +1%","Acima de +1%")) -> Acima de +1% | AF125: =IF($T125<=0.32,"Ate 32%",IF($T125<=0.34,"Ate 34%","Acima de 34%")) -> Ate 32% | AG125: =IF($S125<=0.39,"Ate 39%",IF($S125<=0.41,"Ate 41%","Acima de 41%")) -> Ate 39%
A126: 28.11.2025 - Estação das Fontes III - Escritura+Lançamento - Respostas.pdf | B126: Estação das Fontes III | C126: 45989 | D126: Book de Escritura + Lançamento | E126: Aprovacao | F126: 520 | G126: 190835 | H126: 0.073 | I126: 516 | J126: 45122 | K126: 0.435 | L126: 14 | M126: 86773 | O126: 199568 | P126: 175120 | Q126: 0.216 | R126: 0.2 | S126: 0.433 | T126: 0.346 | U126: 14098 | V126: 0.136 | W126: 2516 | X126: 0.75 | Y126: =(O126-P126)/O126 -> 0.12250461 | Z126: =P126/M126 -> 2.0181393 | AA126: =DATE(YEAR(C126),MONTH(C126),1) -> 45962 | AB126: =IF(X126>=0.5,"Faixa 1",IF(X126=0,"Faixa 3","Faixa 2")) -> Faixa 1 | AC126: 1 | AD126: =YEAR(AA126)&"-"&IF(MONTH(AA126)<4,1,IF(MONTH(AA126)<7,2,IF(MONTH(AA126)<10,3,4)))&"T" -> 2025-4T | AE126: =IF((Q126-R126)<0.005,"Até +0,5%",IF((Q126-R126)<0.01,"Ate +1%","Acima de +1%")) -> Acima de +1% | AF126: =IF($T126<=0.32,"Ate 32%",IF($T126<=0.34,"Ate 34%","Acima de 34%")) -> Acima de 34% | AG126: =IF($S126<=0.39,"Ate 39%",IF($S126<=0.41,"Ate 41%","Acima de 41%")) -> Acima de 41%
A127: 2025.11.28 - Morada Real - Lançamento - Atualizado.pdf | B127: Morada Real | C127: 45989 | D127: Book de Lançamento | E127: Aprovacao | F127: 443 | G127: 248192 | H127: 0.067 | I127: 1165 | J127: 46037 | K127: 0.425 | L127: 20 | M127: 103922 | O127: 244442 | P127: 227661 | Q127: 0.209 | R127: 0.209 | S127: 0.413 | T127: 0.364 | U127: 14195 | V127: 0.134 | W127: 3827 | X127: 0.393 | Y127: =(O127-P127)/O127 -> 0.068650232 | Z127: =P127/M127 -> 2.1906911 | AA127: =DATE(YEAR(C127),MONTH(C127),1) -> 45962 | AB127: =IF(X127>=0.5,"Faixa 1",IF(X127=0,"Faixa 3","Faixa 2")) -> Faixa 2 | AC127: 1 | AD127: =YEAR(AA127)&"-"&IF(MONTH(AA127)<4,1,IF(MONTH(AA127)<7,2,IF(MONTH(AA127)<10,3,4)))&"T" -> 2025-4T | AE127: =IF((Q127-R127)<0.005,"Até +0,5%",IF((Q127-R127)<0.01,"Ate +1%","Acima de +1%")) -> Até +0,5% | AF127: =IF($T127<=0.32,"Ate 32%",IF($T127<=0.34,"Ate 34%","Acima de 34%")) -> Acima de 34% | AG127: =IF($S127<=0.39,"Ate 39%",IF($S127<=0.41,"Ate 41%","Acima de 41%")) -> Acima de 41%
A128: 2025.12.01 - Aurora Iguaçu - Lançamento_R00 1.pdf | B128: Aurora Iguaçu (antigo Vale das águas II) – RBX | C128: 45992 | D128: Book de Lançamento | E128: Aprovacao | F128: 730 | G128: 199353 | H128: 0.053 | I128: 318 | J128: 68307 | K128: 0.472 | L128: 15 | M128: 93571 | O128: 198111 | P128: 180055 | Q128: 0.209 | R128: 0.2 | S128: 0.398 | T128: 0.332 | U128: 13271 | V128: 0.09 | W128: 2376 | X128: 0.717 | Y128: =(O128-P128)/O128 -> 0.091140825 | Z128: =P128/M128 -> 1.9242607 | AA128: =DATE(YEAR(C128),MONTH(C128),1) -> 45992 | AB128: =IF(X128>=0.5,"Faixa 1",IF(X128=0,"Faixa 3","Faixa 2")) -> Faixa 1 | AC128: 1 | AD128: =YEAR(AA128)&"-"&IF(MONTH(AA128)<4,1,IF(MONTH(AA128)<7,2,IF(MONTH(AA128)<10,3,4)))&"T" -> 2025-4T | AE128: =IF((Q128-R128)<0.005,"Até +0,5%",IF((Q128-R128)<0.01,"Ate +1%","Acima de +1%")) -> Ate +1% | AF128: =IF($T128<=0.32,"Ate 32%",IF($T128<=0.34,"Ate 34%","Acima de 34%")) -> Ate 34% | AG128: =IF($S128<=0.39,"Ate 39%",IF($S128<=0.41,"Ate 41%","Acima de 41%")) -> Ate 41%
... A133: 2025.12.01 - Viva Casa Amarela 2 - Investimento _Final.pdf | B133: Viva Casa Amarela 2 | C133: 45992 | D133: Book de Investimento | E133: Aprovacao | F133: 213 | G133: 257981 | H133: 0.077 | I133: 2114 | J133: 24039 | K133: 0.438 | L133: 16 | M133: 112860 | O133: 257543 | P133: 237036 | Q133: 0.202 | R133: 0.2 | S133: 0.38 | T133: 0.32 | U133: 6586 | V133: 0.115 | W133: 3738 | X133: 0.3 | Y133: =(O133-P133)/O133 -> 0.079625538 | Z133: =P133/M133 -> 2.1002658 | AA133: =DATE(YEAR(C133),MONTH(C133),1) -> 45992 | AB133: =IF(X133>=0.5,"Faixa 1",IF(X133=0,"Faixa 3","Faixa 2")) -> Faixa 2 | AC133: 1 | AD133: =YEAR(AA133)&"-"&IF(MONTH(AA133)<4,1,IF(MONTH(AA133)<7,2,IF(MONTH(AA133)<10,3,4)))&"T" -> 2025-4T | AE133: =IF((Q133-R133)<0.005,"Até +0,5%",IF((Q133-R133)<0.01,"Ate +1%","Acima de +1%")) -> Até +0,5% | AF133: =IF($T133<=0.32,"Ate 32%",IF($T133<=0.34,"Ate 34%","Acima de 34%")) -> Ate 32% | AG133: =IF($S133<=0.39,"Ate 39%",IF($S133<=0.41,"Ate 41%","Acima de 41%")) -> Ate 39%
A134: 2025.12.01 - Pirajussara - Essencial de Investimento.pdf | B134: Pirajussara | C134: 45993 | E134: Aprovacao | F134: 1103 | G134: 299691 | H134: 0.17 | I134: 4474 | J134: 111238 | K134: 0.364 | L134: 22 | M134: 100851 | O134: 276768 | P134: 260917 | Q134: 0.2 | R134: 0.2 | S134: 0.378 | T134: 0.335 | U134: 13544 | V134: 0.038 | W134: 5311 | X134: 0.009 | Y134: =(O134-P134)/O134 -> 0.057271794 | Z134: =P134/M134 -> 2.5871533 | AA134: =DATE(YEAR(C134),MONTH(C134),1) -> 45992 | AB134: =IF(X134>=0.5,"Faixa 1",IF(X134=0,"Faixa 3","Faixa 2")) -> Faixa 2 | AC134: 1 | AD134: =YEAR(AA134)&"-"&IF(MONTH(AA134)<4,1,IF(MONTH(AA134)<7,2,IF(MONTH(AA134)<10,3,4)))&"T" -> 2025-4T | AE134: =IF((Q134-R134)<0.005,"Até +0,5%",IF((Q134-R134)<0.01,"Ate +1%","Acima de +1%")) -> Até +0,5% | AF134: =IF($T134<=0.32,"Ate 32%",IF($T134<=0.34,"Ate 34%","Acima de 34%")) -> Ate 34% | AG134: =IF($S134<=0.39,"Ate 39%",IF($S134<=0.41,"Ate 41%","Acima de 41%")) -> Ate 39%
A135: 2025.12.08 - Brumatti Santos - Investimento Ampliado.pdf | B135: Brumatti Santos | C135: 45999 | D135: Book de Investimento - Comitê Ampliado | E135: Aprovacao | F135: 1092 | G135: 254759 | H135: 0.073 | I135: 1063 | J135: 119090 | K135: 0.443 | L135: 22 | M135: 109057 | O135: 246303 | P135: 226264 | Q135: 0.2 | R135: 0.2 | S135: 0.386 | T135: 0.325 | U135: 25678 | V135: 0.088 | W135: 3811 | X135: 0.277 | Y135: =(O135-P135)/O135 -> 0.081359139 | Z135: =P135/M135 -> 2.0747316 | AA135: =DATE(YEAR(C135),MONTH(C135),1) -> 45992 | AB135: =IF(X135>=0.5,"Faixa 1",IF(X135=0,"Faixa 3","Faixa 2")) -> Faixa 2 | AC135: 1 | AD135: =YEAR(AA135)&"-"&IF(MONTH(AA135)<4,1,IF(MONTH(AA135)<7,2,IF(MONTH(AA135)<10,3,4)))&"T" -> 2025-4T | AE135: =IF((Q135-R135)<0.005,"Até +0,5%",IF((Q135-R135)<0.01,"Ate +1%","Acima de +1%")) -> Até +0,5% | AF135: =IF($T135<=0.32,"Ate 32%",IF($T135<=0.34,"Ate 34%","Acima de 34%")) -> Ate 34% | AG135: =IF($S135<=0.39,"Ate 39%",IF($S135<=0.41,"Ate 41%","Acima de 41%")) -> Ate 39%
A136: 2025.12.08 - Cuiabinho - Reversão Essencial.pdf | B136: Cuiabinho | C136: 45999 | D136: Comitê Essencial de Reversão s/ Reneg | E136: Aprovacao | F136: 1140 | G136: 249113 | H136: 0.016 | I136: 360 | J136: 119109 | K136: 0.466 | L136: 23 | M136: 104482 | O136: 224338 | P136: 205299 | Q136: 0.237 | R136: 0.2 | S136: 0.421 | T136: 0.36 | U136: 19604 | V136: 0.07 | W136: 2924 | X136: 0.441 | Y136: =(O136-P136)/O136 -> 0.084867477 | Z136: =P136/M136 -> 1.9649222 | AA136: =DATE(YEAR(C136),MONTH(C136),1) -> 45992 | AB136: =IF(X136>=0.5,"Faixa 1",IF(X136=0,"Faixa 3","Faixa 2")) -> Faixa 2 | AC136: 1 | AD136: =YEAR(AA136)&"-"&IF(MONTH(AA136)<4,1,IF(MONTH(AA136)<7,2,IF(MONTH(AA136)<10,3,4)))&"T" -> 2025-4T | AE136: =IF((Q136-R136)<0.005,"Até +0,5%",IF((Q136-R136)<0.01,"Ate +1%","Acima de +1%")) -> Acima de +1% | AF136: =IF($T136<=0.32,"Ate 32%",IF($T136<=0.34,"Ate 34%","Acima de 34%")) -> Acima de 34% | AG136: =IF($S136<=0.39,"Ate 39%",IF($S136<=0.41,"Ate 41%","Acima de 41%")) -> Acima de 41%
A137: 2025.12.08 - Ferrovila - Investimento REV01.pdf | B137: Ferrovila | C137: 45999 | D137: Comite Ampliado de Investimento | E137: Aprovacao | F137: 783 | G137: 264157 | H137: 0.093 | I137: 1281 | J137: 80412 | K137: 0.395 | L137: 20 | M137: 102698 | O137: 260008 | P137: 237427 | Q137: 0.2 | R137: 0.2 | S137: 0.41 | T137: 0.349 | U137: 18851 | V137: 0.085 | W137: 4298 | X137: 0 | Y137: =(O137-P137)/O137 -> 0.086847328 | Z137: =P137/M137 -> 2.3118951 | AA137: =DATE(YEAR(C137),MONTH(C137),1) -> 45992 | AB137: =IF(X137>=0.5,"Faixa 1",IF(X137=0,"Faixa 3","Faixa 2")) -> Faixa 3 | AC137: 1 | AD137: =YEAR(AA137)&"-"&IF(MONTH(AA137)<4,1,IF(MONTH(AA137)<7,2,IF(MONTH(AA137)<10,3,4)))&"T" -> 2025-4T | AE137: =IF((Q137-R137)<0.005,"Até +0,5%",IF((Q137-R137)<0.01,"Ate +1%","Acima de +1%")) -> Até +0,5% | AF137: =IF($T137<=0.32,"Ate 32%",IF($T137<=0.34,"Ate 34%","Acima de 34%")) -> Acima de 34% | AG137: =IF($S137<=0.39,"Ate 39%",IF($S137<=0.41,"Ate 41%","Acima de 41%")) -> Ate 41%
A138: 2025.12.08 - Laguna Ville - Escritura e Lançamento REV02.1.pdf | B138: Laguna Ville | C138: 45999 | D138: Book de Escritura e Lançamento | E138: Aprovacao | F138: 532 | G138: 219601 | H138: 0.099 | I138: 697 | J138: 49407 | K138: 0.436 | L138: 16 | M138: 92871 | O138: 213044 | P138: 193042 | Q138: 0.202 | R138: 0.2 | S138: 0.384 | T138: 0.314 | U138: 15619 | V138: 0.138 | W138: 2769 | X138: 0.608 | Y138: =(O138-P138)/O138 -> 0.093886709 | Z138: =P138/M138 -> 2.0786037 | AA138: =DATE(YEAR(C138),MONTH(C138),1) -> 45992 | AB138: =IF(X138>=0.5,"Faixa 1",IF(X138=0,"Faixa 3","Faixa 2")) -> Faixa 1 | AC138: 1 | AD138: =YEAR(AA138)&"-"&IF(MONTH(AA138)<4,1,IF(MONTH(AA138)<7,2,IF(MONTH(AA138)<10,3,4)))&"T" -> 2025-4T | AE138: =IF((Q138-R138)<0.005,"Até +0,5%",IF((Q138-R138)<0.01,"Ate +1%","Acima de +1%")) -> Até +0,5% | AF138: =IF($T138<=0.32,"Ate 32%",IF($T138<=0.34,"Ate 34%","Acima de 34%")) -> Ate 32% | AG138: =IF($S138<=0.39,"Ate 39%",IF($S138<=0.41,"Ate 41%","Acima de 41%")) -> Ate 39%
A139: 2025.12.09 - Protendit - Essencial_v1 2.pdf | B139: Pedro de Castilho (PROTENDIT) | C139: 45999 | E139: Aprovacao | F139: 952 | G139: 230000 | H139: 0.099 | I139: 2086 | J139: 93190 | K139: 0.447 | L139: 25 | M139: 97888 | O139: 219216 | P139: 197616 | Q139: 0.201 | R139: 0.2 | S139: 0.36 | T139: 0.28 | U139: 15303 | V139: 0.067 | W139: 2573 | X139: 0.75 | Y139: =(O139-P139)/O139 -> 0.098532954 | Z139: =P139/M139 -> 2.018797 | AA139: =DATE(YEAR(C139),MONTH(C139),1) -> 45992 | AB139: =IF(X139>=0.5,"Faixa 1",IF(X139=0,"Faixa 3","Faixa 2")) -> Faixa 1 | AC139: 1 | AD139: =YEAR(AA139)&"-"&IF(MONTH(AA139)<4,1,IF(MONTH(AA139)<7,2,IF(MONTH(AA139)<10,3,4)))&"T" -> 2025-4T | AE139: =IF((Q139-R139)<0.005,"Até +0,5%",IF((Q139-R139)<0.01,"Ate +1%","Acima de +1%")) -> Até +0,5% | AF139: =IF($T139<=0.32,"Ate 32%",IF($T139<=0.34,"Ate 34%","Acima de 34%")) -> Ate 32% | AG139: =IF($S139<=0.39,"Ate 39%",IF($S139<=0.41,"Ate 41%","Acima de 41%")) -> Ate 39%
A140: 2025.12.08 - Vista Paraná - Ampliado de Investimento R00.pdf | B140: Vista Paraná– RZN3 | C140: 45999 | D140: Book de Investimento | E140: Aprovacao | F140: 285 | G140: 250807 | H140: 0.044 | I140: 992 | J140: 32482 | K140: 0.464 | L140: 16 | M140: 113972 | O140: 245737 | P140: 225489 | Q140: 0.201 | R140: 0.2 | S140: 0.401 | T140: 0.342 | U140: 11516 | V140: 0.156 | W140: 4100 | X140: 0 | Y140: =(O140-P140)/O140 -> 0.082397034 | Z140: =P140/M140 -> 1.9784596 | AA140: =DATE(YEAR(C140),MONTH(C140),1) -> 45992 | AB140: =IF(X140>=0.5,"Faixa 1",IF(X140=0,"Faixa 3","Faixa 2")) -> Faixa 3 | AC140: 1 | AD140: =YEAR(AA140)&"-"&IF(MONTH(AA140)<4,1,IF(MONTH(AA140)<7,2,IF(MONTH(AA140)<10,3,4)))&"T" -> 2025-4T | AE140: =IF((Q140-R140)<0.005,"Até +0,5%",IF((Q140-R140)<0.01,"Ate +1%","Acima de +1%")) -> Até +0,5% | AF140: =IF($T140<=0.32,"Ate 32%",IF($T140<=0.34,"Ate 34%","Acima de 34%")) -> Acima de 34% | AG140: =IF($S140<=0.39,"Ate 39%",IF($S140<=0.41,"Ate 41%","Acima de 41%")) -> Ate 41%
A141: 2025.12.12 - Bandeirante -Escrit + Lançamento_Respostas.pdf | B141: Bandeirante | C141: 46003 | D141: Book de Escritura + Lançamento | E141: Aprovacao | F141: 444 | G141: 209432 | H141: 0.061 | I141: 595 | J141: 44228 | K141: 0.457 | L141: 19 | M141: 99613 | O141: 217978 | P141: 197100 | Q141: 0.19 | R141: 0.2 | S141: 0.396 | T141: 0.325 | U141: 16218 | V141: 0.169 | W141: 2966 | X141: 0.493 | Y141: =(O141-P141)/O141 -> 0.095780308 | Z141: =P141/M141 -> 1.9786574 | AA141: =DATE(YEAR(C141),MONTH(C141),1) -> 45992 | AB141: =IF(X141>=0.5,"Faixa 1",IF(X141=0,"Faixa 3","Faixa 2")) -> Faixa 2 | AC141: 1 | AD141: =YEAR(AA141)&"-"&IF(MONTH(AA141)<4,1,IF(MONTH(AA141)<7,2,IF(MONTH(AA141)<10,3,4)))&"T" -> 2025-4T | AE141: =IF((Q141-R141)<0.005,"Até +0,5%",IF((Q141-R141)<0.01,"Ate +1%","Acima de +1%")) -> Até +0,5% | AF141: =IF($T141<=0.32,"Ate 32%",IF($T141<=0.34,"Ate 34%","Acima de 34%")) -> Ate 34% | AG141: =IF($S141<=0.39,"Ate 39%",IF($S141<=0.41,"Ate 41%","Acima de 41%")) -> Ate 41%
A142: 2025.12.12 - Elevato Inhaúma - Ampliado de Investimento_Respostas R01.pdf | B142: Elevato Inhaúma – RZN2 | C142: 46003 | D142: Book de Investimento | E142: Aprovacao | F142: 496 | G142: 240000 | H142: 0.07 | I142: 1561 | J142: 49492 | K142: 0.437 | L142: 18 | M142: 99782 | O142: 228529 | P142: 204827 | Q142: 0.2 | R142: 0.2 | S142: 0.402 | T142: 0.325 | U142: 15876 | V142: 0.131 | W142: 3563 | X142: 0.25 | Y142: =(O142-P142)/O142 -> 0.1037155 | Z142: =P142/M142 -> 2.052745 | AA142: =DATE(YEAR(C142),MONTH(C142),1) -> 45992 | AB142: =IF(X142>=0.5,"Faixa 1",IF(X142=0,"Faixa 3","Faixa 2")) -> Faixa 2 | AC142: 1 | AD142: =YEAR(AA142)&"-"&IF(MONTH(AA142)<4,1,IF(MONTH(AA142)<7,2,IF(MONTH(AA142)<10,3,4)))&"T" -> 2025-4T | AE142: =IF((Q142-R142)<0.005,"Até +0,5%",IF((Q142-R142)<0.01,"Ate +1%","Acima de +1%")) -> Até +0,5% | AF142: =IF($T142<=0.32,"Ate 32%",IF($T142<=0.34,"Ate 34%","Acima de 34%")) -> Ate 34% | AG142: =IF($S142<=0.39,"Ate 39%",IF($S142<=0.41,"Ate 41%","Acima de 41%")) -> Ate 41%
A143: 2025.12.12 - Pituba Prime - Investimento REV03_Resposta.pdf | B143: Pituba Prime | C143: 46003 | D143: Book de Investimento | E143: Aprovacao | F143: 428 | G143: 297220 | H143: 0.105 | I143: 2902 | J143: 48140 | K143: 0.388 | L143: 20 | M143: 112476 | O143: 289733 | P143: 266959 | Q143: 0.224 | R143: 0.2 | S143: 0.419 | T143: 0.363 | U143: 10380 | V143: 0.081 | W143: 5876 | X143: 0 | Y143: =(O143-P143)/O143 -> 0.078603404 | Z143: =P143/M143 -> 2.3734752 | AA143: =DATE(YEAR(C143),MONTH(C143),1) -> 45992 | AB143: =IF(X143>=0.5,"Faixa 1",IF(X143=0,"Faixa 3","Faixa 2")) -> Faixa 3 | AC143: 1 | AD143: =YEAR(AA143)&"-"&IF(MONTH(AA143)<4,1,IF(MONTH(AA143)<7,2,IF(MONTH(AA143)<10,3,4)))&"T" -> 2025-4T | AE143: =IF((Q143-R143)<0.005,"Até +0,5%",IF((Q143-R143)<0.01,"Ate +1%","Acima de +1%")) -> Acima de +1% | AF143: =IF($T143<=0.32,"Ate 32%",IF($T143<=0.34,"Ate 34%","Acima de 34%")) -> Acima de 34% | AG143: =IF($S143<=0.39,"Ate 39%",IF($S143<=0.41,"Ate 41%","Acima de 41%")) -> Acima de 41%
A144: 2025.12.12 - Vila Butanta - Rev +Escr + Lçto - Respostas.pdf | B144: Vila Butantã (Joaquim Guimarães) | C144: 46003 | D144: Book de Escritura + Lançamento | E144: Aprovacao | F144: 796 | G144: 268088 | H144: 0.079 | I144: 3621 | J144: 85911 | K144: 0.45 | L144: 27 | M144: 107929 | O144: 239881 | P144: 219296 | Q144: 0.2 | R144: 0.2 | S144: 0.371 | T144: 0.303 | U144: 11753 | V144: 0.062 | W144: 3700 | X144: 0.203 | Y144: =(O144-P144)/O144 -> 0.085813382 | Z144: =P144/M144 -> 2.0318543 | AA144: =DATE(YEAR(C144),MONTH(C144),1) -> 45992 | AB144: =IF(X144>=0.5,"Faixa 1",IF(X144=0,"Faixa 3","Faixa 2")) -> Faixa 2 | AC144: 1 | AD144: =YEAR(AA144)&"-"&IF(MONTH(AA144)<4,1,IF(MONTH(AA144)<7,2,IF(MONTH(AA144)<10,3,4)))&"T" -> 2025-4T | AE144: =IF((Q144-R144)<0.005,"Até +0,5%",IF((Q144-R144)<0.01,"Ate +1%","Acima de +1%")) -> Até +0,5% | AF144: =IF($T144<=0.32,"Ate 32%",IF($T144<=0.34,"Ate 34%","Acima de 34%")) -> Ate 32% | AG144: =IF($S144<=0.39,"Ate 39%",IF($S144<=0.41,"Ate 41%","Acima de 41%")) -> Ate 39%
A145: 2025.12.15 - Laranjal - Book Essencial EE.pdf | B145: Laranjal | C145: 46006 | D145: Comitê Essencial | E145: Aprovacao | F145: 568 | G145: 236900 | H145: 0.031 | I145: 400 | J145: 61773 | K145: 0.475 | L145: 21 | M145: 108756 | O145: 228739 | P145: 209271 | Q145: 0.218 | R145: 0.2 | S145: 0.402 | T145: 0.339 | U145: 16017 | V145: 0.112 | W145: 2964 | X145: 0.411 | Y145: =(O145-P145)/O145 -> 0.085110104 | Z145: =P145/M145 -> 1.9242249 | AA145: =DATE(YEAR(C145),MONTH(C145),1) -> 45992 | AB145: =IF(X145>=0.5,"Faixa 1",IF(X145=0,"Faixa 3","Faixa 2")) -> Faixa 2 | AC145: 1 | AD145: =YEAR(AA145)&"-"&IF(MONTH(AA145)<4,1,IF(MONTH(AA145)<7,2,IF(MONTH(AA145)<10,3,4)))&"T" -> 2025-4T | AE145: =IF((Q145-R145)<0.005,"Até +0,5%",IF((Q145-R145)<0.01,"Ate +1%","Acima de +1%")) -> Acima de +1% | AF145: =IF($T145<=0.32,"Ate 32%",IF($T145<=0.34,"Ate 34%","Acima de 34%")) -> Ate 34% | AG145: =IF($S145<=0.39,"Ate 39%",IF($S145<=0.41,"Ate 41%","Acima de 41%")) -> Ate 41%
...

Sheet Planilha2
B4: QTD PROJETOS COMITÊ
B5: TRI | C5: FAIXA 1 | D5: FAIXA 2 | E5: FAIXA 3 | F5: TOTAL
B6: 2025-1T | C6: =COUNTIFS(dados_filtrado!$AB:$AB,Planilha2!C$5,dados_filtrado!$AD:$AD,Planilha2!$B6) -> 5 | D6: =COUNTIFS(dados_filtrado!$AB:$AB,Planilha2!D$5,dados_filtrado!$AD:$AD,Planilha2!$B6) -> 7 | E6: =COUNTIFS(dados_filtrado!$AB:$AB,Planilha2!E$5,dados_filtrado!$AD:$AD,Planilha2!$B6) -> 3 | F6: =SUM(C6:E6) -> 15
B7: 2025-2T | C7: =COUNTIFS(dados_filtrado!$AB:$AB,Planilha2!C$5,dados_filtrado!$AD:$AD,Planilha2!$B7) -> 15 | D7: =COUNTIFS(dados_filtrado!$AB:$AB,Planilha2!D$5,dados_filtrado!$AD:$AD,Planilha2!$B7) -> 27 | E7: =COUNTIFS(dados_filtrado!$AB:$AB,Planilha2!E$5,dados_filtrado!$AD:$AD,Planilha2!$B7) -> 7 | F7: =SUM(C7:E7) -> 49
B8: 2025-3T | C8: =COUNTIFS(dados_filtrado!$AB:$AB,Planilha2!C$5,dados_filtrado!$AD:$AD,Planilha2!$B8) -> 4 | D8: =COUNTIFS(dados_filtrado!$AB:$AB,Planilha2!D$5,dados_filtrado!$AD:$AD,Planilha2!$B8) -> 20 | E8: =COUNTIFS(dados_filtrado!$AB:$AB,Planilha2!E$5,dados_filtrado!$AD:$AD,Planilha2!$B8) -> 10 | F8: =SUM(C8:E8) -> 34
B9: 2025-4T | C9: =COUNTIFS(dados_filtrado!$AB:$AB,Planilha2!C$5,dados_filtrado!$AD:$AD,Planilha2!$B9) -> 12 | D9: =COUNTIFS(dados_filtrado!$AB:$AB,Planilha2!D$5,dados_filtrado!$AD:$AD,Planilha2!$B9) -> 24 | E9: =COUNTIFS(dados_filtrado!$AB:$AB,Planilha2!E$5,dados_filtrado!$AD:$AD,Planilha2!$B9) -> 14 | F9: =SUM(C9:E9) -> 50
B10: 2026-1T | C10: =COUNTIFS(dados_filtrado!$AB:$AB,Planilha2!C$5,dados_filtrado!$AD:$AD,Planilha2!$B10) -> 8 | D10: =COUNTIFS(dados_filtrado!$AB:$AB,Planilha2!D$5,dados_filtrado!$AD:$AD,Planilha2!$B10) -> 6 | E10: =COUNTIFS(dados_filtrado!$AB:$AB,Planilha2!E$5,dados_filtrado!$AD:$AD,Planilha2!$B10) -> 8 | F10: =SUM(C10:E10) -> 22
B12: PREÇO RASO / CUSTO
B13: TRI | C13: FAIXA 1 | D13: FAIXA 2 | E13: FAIXA 3 | F13: TOTAL
B14: 2025-1T | C14: =AVERAGEIFS(dados_filtrado!$Z:$Z,dados_filtrado!$AB:$AB,Planilha2!C$5,dados_filtrado!$AD:$AD,Planilha2!$B14) -> 1.999608 | D14: =AVERAGEIFS(dados_filtrado!$Z:$Z,dados_filtrado!$AB:$AB,Planilha2!D$5,dados_filtrado!$AD:$AD,Planilha2!$B14) -> 2.1464421 | E14: =AVERAGEIFS(dados_filtrado!$Z:$Z,dados_filtrado!$AB:$AB,Planilha2!E$5,dados_filtrado!$AD:$AD,Planilha2!$B14) -> 2.5027137 | F14: =AVERAGEIFS(dados_filtrado!$Z:$Z,dados_filtrado!$AD:$AD,Planilha2!$B14) -> 2.1687517
B15: 2025-2T | C15: =AVERAGEIFS(dados_filtrado!$Z:$Z,dados_filtrado!$AB:$AB,Planilha2!C$5,dados_filtrado!$AD:$AD,Planilha2!$B15) -> 2.0045121 | D15: =AVERAGEIFS(dados_filtrado!$Z:$Z,dados_filtrado!$AB:$AB,Planilha2!D$5,dados_filtrado!$AD:$AD,Planilha2!$B15) -> 2.1121961 | E15: =AVERAGEIFS(dados_filtrado!$Z:$Z,dados_filtrado!$AB:$AB,Planilha2!E$5,dados_filtrado!$AD:$AD,Planilha2!$B15) -> 2.3511835 | F15: =AVERAGEIFS(dados_filtrado!$Z:$Z,dados_filtrado!$AD:$AD,Planilha2!$B15) -> 2.1133727
B16: 2025-3T | C16: =AVERAGEIFS(dados_filtrado!$Z:$Z,dados_filtrado!$AB:$AB,Planilha2!C$5,dados_filtrado!$AD:$AD,Planilha2!$B16) -> 2.0961373 | D16: =AVERAGEIFS(dados_filtrado!$Z:$Z,dados_filtrado!$AB:$AB,Planilha2!D$5,dados_filtrado!$AD:$AD,Planilha2!$B16) -> 2.1419669 | E16: =AVERAGEIFS(dados_filtrado!$Z:$Z,dados_filtrado!$AB:$AB,Planilha2!E$5,dados_filtrado!$AD:$AD,Planilha2!$B16) -> 2.3355619 | F16: =AVERAGEIFS(dados_filtrado!$Z:$Z,dados_filtrado!$AD:$AD,Planilha2!$B16) -> 2.1935149
